Workbook

Sheet Summary
A1: EdVidura Master Checklist v3 — remediated delivery system
A2: 2120 items (1830 carried from v2 + 290 added by audit) · 43 products · 8 squads + QA guild · 9 test teams · 6 stages
A3: v3 applies the audit fixes: India re-basing, 11 new delivery-management sheets, 7 new columns, controlled vocabularies, conditional formatting, protection and a change log.
A4: YELLOW = you fill in. Start with Assignee on Stage 0–1 rows, then EstDays, then the Sprint Calendar and Capacity sheets.
A6: Locked provisional decisions
A7: Metabase edition | B7: OSS; tenant isolation at DB level (RLS / per-tenant schemas); signed static embedding
A8: Tenancy model | B8: Hybrid — shared schema + RLS for SaaS tenants; instance-per-command/organisation for enclaves
A9: Accreditation authority | B9: Deferred by direction — product renamed market-neutral; authority is a Human-Input entry, no authority asserted
A10: Market | B10: India-first, with air-gapped/enclave capability retained; immersive labs are now a repeatable India lab product
A11: Event transport | B11: PostgreSQL transactional outbox + workers first; broker promotion later
A12: Local AI | B12: One shared local-inference platform (E04) consumed by every AI module
A15: Progress by squad (live)
A16: Squad | B16: Build | C16: Test | D16: Total | E16: Done | F16: In progress | G16: Blocked | H16: % done | I16: Unassigned | J16: Est. days
A17: SQ1 Platform Core | B17: =COUNTIFS('Master Checklist'!$H:$H,$A17,'Master Checklist'!$D:$D,"Build") -> 290 | C17: =COUNTIFS('Master Checklist'!$H:$H,$A17,'Master Checklist'!$D:$D,"Test") -> 27 | D17: =COUNTIF('Master Checklist'!$H:$H,$A17) -> 317 | E17: =COUNTIFS('Master Checklist'!$H:$H,$A17,'Master Checklist'!$Y:$Y,"Done") -> 0 | F17: =COUNTIFS('Master Checklist'!$H:$H,$A17,'Master Checklist'!$Y:$Y,"In progress") -> 0 | G17: =COUNTIFS('Master Checklist'!$H:$H,$A17,'Master Checklist'!$Y:$Y,"Blocked") -> 0 | H17: =IF(D17=0,0,E17/D17) -> 0 | I17: =COUNTIFS('Master Checklist'!$H:$H,$A17,'Master Checklist'!$L:$L,"") -> 317 | J17: =SUMIF('Master Checklist'!$H:$H,$A17,'Master Checklist'!$M:$M) -> 0
A18: SQ2 Learning Tools | B18: =COUNTIFS('Master Checklist'!$H:$H,$A18,'Master Checklist'!$D:$D,"Build") -> 277 | C18: =COUNTIFS('Master Checklist'!$H:$H,$A18,'Master Checklist'!$D:$D,"Test") -> 58 | D18: =COUNTIF('Master Checklist'!$H:$H,$A18) -> 335 | E18: =COUNTIFS('Master Checklist'!$H:$H,$A18,'Master Checklist'!$Y:$Y,"Done") -> 0 | F18: =COUNTIFS('Master Checklist'!$H:$H,$A18,'Master Checklist'!$Y:$Y,"In progress") -> 0 | G18: =COUNTIFS('Master Checklist'!$H:$H,$A18,'Master Checklist'!$Y:$Y,"Blocked") -> 0 | H18: =IF(D18=0,0,E18/D18) -> 0 | I18: =COUNTIFS('Master Checklist'!$H:$H,$A18,'Master Checklist'!$L:$L,"") -> 335 | J18: =SUMIF('Master Checklist'!$H:$H,$A18,'Master Checklist'!$M:$M) -> 0
A19: SQ3 Data & Analytics | B19: =COUNTIFS('Master Checklist'!$H:$H,$A19,'Master Checklist'!$D:$D,"Build") -> 183 | C19: =COUNTIFS('Master Checklist'!$H:$H,$A19,'Master Checklist'!$D:$D,"Test") -> 19 | D19: =COUNTIF('Master Checklist'!$H:$H,$A19) -> 202 | E19: =COUNTIFS('Master Checklist'!$H:$H,$A19,'Master Checklist'!$Y:$Y,"Done") -> 0 | F19: =COUNTIFS('Master Checklist'!$H:$H,$A19,'Master Checklist'!$Y:$Y,"In progress") -> 0 | G19: =COUNTIFS('Master Checklist'!$H:$H,$A19,'Master Checklist'!$Y:$Y,"Blocked") -> 0 | H19: =IF(D19=0,0,E19/D19) -> 0 | I19: =COUNTIFS('Master Checklist'!$H:$H,$A19,'Master Checklist'!$L:$L,"") -> 202 | J19: =SUMIF('Master Checklist'!$H:$H,$A19,'Master Checklist'!$M:$M) -> 0
A20: SQ4 TLA & Federation | B20: =COUNTIFS('Master Checklist'!$H:$H,$A20,'Master Checklist'!$D:$D,"Build") -> 225 | C20: =COUNTIFS('Master Checklist'!$H:$H,$A20,'Master Checklist'!$D:$D,"Test") -> 39 | D20: =COUNTIF('Master Checklist'!$H:$H,$A20) -> 264 | E20: =COUNTIFS('Master Checklist'!$H:$H,$A20,'Master Checklist'!$Y:$Y,"Done") -> 0 | F20: =COUNTIFS('Master Checklist'!$H:$H,$A20,'Master Checklist'!$Y:$Y,"In progress") -> 0 | G20: =COUNTIFS('Master Checklist'!$H:$H,$A20,'Master Checklist'!$Y:$Y,"Blocked") -> 0 | H20: =IF(D20=0,0,E20/D20) -> 0 | I20: =COUNTIFS('Master Checklist'!$H:$H,$A20,'Master Checklist'!$L:$L,"") -> 264 | J20: =SUMIF('Master Checklist'!$H:$H,$A20,'Master Checklist'!$M:$M) -> 0
A21: SQ5 AI & Assessment | B21: =COUNTIFS('Master Checklist'!$H:$H,$A21,'Master Checklist'!$D:$D,"Build") -> 270 | C21: =COUNTIFS('Master Checklist'!$H:$H,$A21,'Master Checklist'!$D:$D,"Test") -> 34 | D21: =COUNTIF('Master Checklist'!$H:$H,$A21) -> 304 | E21: =COUNTIFS('Master Checklist'!$H:$H,$A21,'Master Checklist'!$Y:$Y,"Done") -> 0 | F21: =COUNTIFS('Master Checklist'!$H:$H,$A21,'Master Checklist'!$Y:$Y,"In progress") -> 0 | G21: =COUNTIFS('Master Checklist'!$H:$H,$A21,'Master Checklist'!$Y:$Y,"Blocked") -> 0 | H21: =IF(D21=0,0,E21/D21) -> 0 | I21: =COUNTIFS('Master Checklist'!$H:$H,$A21,'Master Checklist'!$L:$L,"") -> 304 | J21: =SUMIF('Master Checklist'!$H:$H,$A21,'Master Checklist'!$M:$M) -> 0
A22: SQ6 Content & Authoring | B22: =COUNTIFS('Master Checklist'!$H:$H,$A22,'Master Checklist'!$D:$D,"Build") -> 131 | C22: =COUNTIFS('Master Checklist'!$H:$H,$A22,'Master Checklist'!$D:$D,"Test") -> 26 | D22: =COUNTIF('Master Checklist'!$H:$H,$A22) -> 157 | E22: =COUNTIFS('Master Checklist'!$H:$H,$A22,'Master Checklist'!$Y:$Y,"Done") -> 0 | F22: =COUNTIFS('Master Checklist'!$H:$H,$A22,'Master Checklist'!$Y:$Y,"In progress") -> 0 | G22: =COUNTIFS('Master Checklist'!$H:$H,$A22,'Master Checklist'!$Y:$Y,"Blocked") -> 0 | H22: =IF(D22=0,0,E22/D22) -> 0 | I22: =COUNTIFS('Master Checklist'!$H:$H,$A22,'Master Checklist'!$L:$L,"") -> 157 | J22: =SUMIF('Master Checklist'!$H:$H,$A22,'Master Checklist'!$M:$M) -> 0
A23: SQ7 Field & Immersive | B23: =COUNTIFS('Master Checklist'!$H:$H,$A23,'Master Checklist'!$D:$D,"Build") -> 227 | C23: =COUNTIFS('Master Checklist'!$H:$H,$A23,'Master Checklist'!$D:$D,"Test") -> 44 | D23: =COUNTIF('Master Checklist'!$H:$H,$A23) -> 271 | E23: =COUNTIFS('Master Checklist'!$H:$H,$A23,'Master Checklist'!$Y:$Y,"Done") -> 0 | F23: =COUNTIFS('Master Checklist'!$H:$H,$A23,'Master Checklist'!$Y:$Y,"In progress") -> 0 | G23: =COUNTIFS('Master Checklist'!$H:$H,$A23,'Master Checklist'!$Y:$Y,"Blocked") -> 0 | H23: =IF(D23=0,0,E23/D23) -> 0 | I23: =COUNTIFS('Master Checklist'!$H:$H,$A23,'Master Checklist'!$L:$L,"") -> 271 | J23: =SUMIF('Master Checklist'!$H:$H,$A23,'Master Checklist'!$M:$M) -> 0
A24: SQ8 Program & Governance | B24: =COUNTIFS('Master Checklist'!$H:$H,$A24,'Master Checklist'!$D:$D,"Build") -> 192 | C24: =COUNTIFS('Master Checklist'!$H:$H,$A24,'Master Checklist'!$D:$D,"Test") -> 0 | D24: =COUNTIF('Master Checklist'!$H:$H,$A24) -> 192 | E24: =COUNTIFS('Master Checklist'!$H:$H,$A24,'Master Checklist'!$Y:$Y,"Done") -> 0 | F24: =COUNTIFS('Master Checklist'!$H:$H,$A24,'Master Checklist'!$Y:$Y,"In progress") -> 0 | G24: =COUNTIFS('Master Checklist'!$H:$H,$A24,'Master Checklist'!$Y:$Y,"Blocked") -> 0 | H24: =IF(D24=0,0,E24/D24) -> 0 | I24: =COUNTIFS('Master Checklist'!$H:$H,$A24,'Master Checklist'!$L:$L,"") -> 192 | J24: =SUMIF('Master Checklist'!$H:$H,$A24,'Master Checklist'!$M:$M) -> 0
A25: QA Guild | B25: =COUNTIFS('Master Checklist'!$H:$H,$A25,'Master Checklist'!$D:$D,"Build") -> 0 | C25: =COUNTIFS('Master Checklist'!$H:$H,$A25,'Master Checklist'!$D:$D,"Test") -> 78 | D25: =COUNTIF('Master Checklist'!$H:$H,$A25) -> 78 | E25: =COUNTIFS('Master Checklist'!$H:$H,$A25,'Master Checklist'!$Y:$Y,"Done") -> 0 | F25: =COUNTIFS('Master Checklist'!$H:$H,$A25,'Master Checklist'!$Y:$Y,"In progress") -> 0 | G25: =COUNTIFS('Master Checklist'!$H:$H,$A25,'Master Checklist'!$Y:$Y,"Blocked") -> 0 | H25: =IF(D25=0,0,E25/D25) -> 0 | I25: =COUNTIFS('Master Checklist'!$H:$H,$A25,'Master Checklist'!$L:$L,"") -> 78 | J25: =SUMIF('Master Checklist'!$H:$H,$A25,'Master Checklist'!$M:$M) -> 0
A26: TOTAL | B26: =SUM(B17:B25) -> 1795 | C26: =SUM(C17:C25) -> 325 | D26: =SUM(D17:D25) -> 2120 | E26: =SUM(E17:E25) -> 0 | F26: =SUM(F17:F25) -> 0 | G26: =SUM(G17:G25) -> 0 | H26: =IF(D26=0,0,E26/D26) -> 0 | I26: =SUM(I17:I25) -> 2120 | J26: =SUM(J17:J25) -> 0
A28: Progress by stage (live)
A29: Stage | B29: Scope | C29: Build | D29: Test | E29: Total | F29: Done | G29: % done | H29: P0 open
A30: 0 | B30: Stage 0 — Contracts, schemas & decisions | C30: =COUNTIFS('Master Checklist'!$O:$O,$A30,'Master Checklist'!$D:$D,"Build") -> 292 | D30: =COUNTIFS('Master Checklist'!$O:$O,$A30,'Master Checklist'!$D:$D,"Test") -> 0 | E30: =COUNTIF('Master Checklist'!$O:$O,$A30) -> 292 | F30: =COUNTIFS('Master Checklist'!$O:$O,$A30,'Master Checklist'!$Y:$Y,"Done") -> 0 | G30: =IF(E30=0,0,F30/E30) -> 0 | H30: =COUNTIFS('Master Checklist'!$O:$O,$A30,'Master Checklist'!$E:$E,"P0",'Master Checklist'!$Y:$Y,"<>Done") -> 25
A31: 1 | B31: Stage 1 — Slice A validation | C31: =COUNTIFS('Master Checklist'!$O:$O,$A31,'Master Checklist'!$D:$D,"Build") -> 367 | D31: =COUNTIFS('Master Checklist'!$O:$O,$A31,'Master Checklist'!$D:$D,"Test") -> 131 | E31: =COUNTIF('Master Checklist'!$O:$O,$A31) -> 498 | F31: =COUNTIFS('Master Checklist'!$O:$O,$A31,'Master Checklist'!$Y:$Y,"Done") -> 0 | G31: =IF(E31=0,0,F31/E31) -> 0 | H31: =COUNTIFS('Master Checklist'!$O:$O,$A31,'Master Checklist'!$E:$E,"P0",'Master Checklist'!$Y:$Y,"<>Done") -> 13
A32: 2 | B32: Stage 2 — Content & competency | C32: =COUNTIFS('Master Checklist'!$O:$O,$A32,'Master Checklist'!$D:$D,"Build") -> 438 | D32: =COUNTIFS('Master Checklist'!$O:$O,$A32,'Master Checklist'!$D:$D,"Test") -> 58 | E32: =COUNTIF('Master Checklist'!$O:$O,$A32) -> 496 | F32: =COUNTIFS('Master Checklist'!$O:$O,$A32,'Master Checklist'!$Y:$Y,"Done") -> 0 | G32: =IF(E32=0,0,F32/E32) -> 0 | H32: =COUNTIFS('Master Checklist'!$O:$O,$A32,'Master Checklist'!$E:$E,"P0",'Master Checklist'!$Y:$Y,"<>Done") -> 6
A33: 3 | B33: Stage 3 — AI & field slices | C33: =COUNTIFS('Master Checklist'!$O:$O,$A33,'Master Checklist'!$D:$D,"Build") -> 428 | D33: =COUNTIFS('Master Checklist'!$O:$O,$A33,'Master Checklist'!$D:$D,"Test") -> 85 | E33: =COUNTIF('Master Checklist'!$O:$O,$A33) -> 513 | F33: =COUNTIFS('Master Checklist'!$O:$O,$A33,'Master Checklist'!$Y:$Y,"Done") -> 0 | G33: =IF(E33=0,0,F33/E33) -> 0 | H33: =COUNTIFS('Master Checklist'!$O:$O,$A33,'Master Checklist'!$E:$E,"P0",'Master Checklist'!$Y:$Y,"<>Done") -> 6
A34: 4 | B34: Stage 4 — Controlled pilot | C34: =COUNTIFS('Master Checklist'!$O:$O,$A34,'Master Checklist'!$D:$D,"Build") -> 173 | D34: =COUNTIFS('Master Checklist'!$O:$O,$A34,'Master Checklist'!$D:$D,"Test") -> 39 | E34: =COUNTIF('Master Checklist'!$O:$O,$A34) -> 212 | F34: =COUNTIFS('Master Checklist'!$O:$O,$A34,'Master Checklist'!$Y:$Y,"Done") -> 0 | G34: =IF(E34=0,0,F34/E34) -> 0 | H34: =COUNTIFS('Master Checklist'!$O:$O,$A34,'Master Checklist'!$E:$E,"P0",'Master Checklist'!$Y:$Y,"<>Done") -> 0
A35: 5 | B35: Stage 5 — Production & scale | C35: =COUNTIFS('Master Checklist'!$O:$O,$A35,'Master Checklist'!$D:$D,"Build") -> 97 | D35: =COUNTIFS('Master Checklist'!$O:$O,$A35,'Master Checklist'!$D:$D,"Test") -> 12 | E35: =COUNTIF('Master Checklist'!$O:$O,$A35) -> 109 | F35: =COUNTIFS('Master Checklist'!$O:$O,$A35,'Master Checklist'!$Y:$Y,"Done") -> 0 | G35: =IF(E35=0,0,F35/E35) -> 0 | H35: =COUNTIFS('Master Checklist'!$O:$O,$A35,'Master Checklist'!$E:$E,"P0",'Master Checklist'!$Y:$Y,"<>Done") -> 0

Sheet Product Index
A1: Product / Deliverable Index — 30 client deliverables + 13 enabling products
A2: Renamed products are marked. Yellow = assign owners. Counts are live.
A4: ProductID | B4: Product / deliverable | C4: Type | D4: Primary squad | E4: Modules | F4: Product owner | G4: Tech lead | H4: QA lead | I4: Build | J4: Test | K4: Total | L4: Stage span | M4: Done | N4: % done | O4: Blocked | P4: Renamed in v3
A5: D01 | B5: AI SME Chatbot — Learner-Facing | C5: Client deliverable | D5: SQ5 AI & Assessment | E5: M15, M26 | I5: =COUNTIFS('Master Checklist'!$B:$B,$A5,'Master Checklist'!$D:$D,"Build") -> 89 | J5: =COUNTIFS('Master Checklist'!$B:$B,$A5,'Master Checklist'!$D:$D,"Test") -> 14 | K5: =COUNTIF('Master Checklist'!$B:$B,$A5) -> 103 | L5: Stage 0–3 | M5: =COUNTIFS('Master Checklist'!$B:$B,$A5,'Master Checklist'!$Y:$Y,"Done") -> 0 | N5: =IF(K5=0,0,M5/K5) -> 0 | O5: =COUNTIFS('Master Checklist'!$B:$B,$A5,'Master Checklist'!$Y:$Y,"Blocked") -> 0
A6: D02 | B6: AI Assessment Tools & Test Banks + Auto Grader | C6: Client deliverable | D6: SQ5 AI & Assessment | E6: M8, M27 | I6: =COUNTIFS('Master Checklist'!$B:$B,$A6,'Master Checklist'!$D:$D,"Build") -> 84 | J6: =COUNTIFS('Master Checklist'!$B:$B,$A6,'Master Checklist'!$D:$D,"Test") -> 14 | K6: =COUNTIF('Master Checklist'!$B:$B,$A6) -> 98 | L6: Stage 0–3 | M6: =COUNTIFS('Master Checklist'!$B:$B,$A6,'Master Checklist'!$Y:$Y,"Done") -> 0 | N6: =IF(K6=0,0,M6/K6) -> 0 | O6: =COUNTIFS('Master Checklist'!$B:$B,$A6,'Master Checklist'!$Y:$Y,"Blocked") -> 0
A7: D03 | B7: Security Accreditation & Authorisation to Operate — Initiation | C7: Client deliverable | D7: SQ8 Program & Governance | E7: P1, SVC | I7: =COUNTIFS('Master Checklist'!$B:$B,$A7,'Master Checklist'!$D:$D,"Build") -> 17 | J7: =COUNTIFS('Master Checklist'!$B:$B,$A7,'Master Checklist'!$D:$D,"Test") -> 0 | K7: =COUNTIF('Master Checklist'!$B:$B,$A7) -> 17 | L7: Stage 0–1 | M7: =COUNTIFS('Master Checklist'!$B:$B,$A7,'Master Checklist'!$Y:$Y,"Done") -> 0 | N7: =IF(K7=0,0,M7/K7) -> 0 | O7: =COUNTIFS('Master Checklist'!$B:$B,$A7,'Master Checklist'!$Y:$Y,"Blocked") -> 0 | P7: was: ATO Initiation — AFGSC
A8: D04 | B8: Pedagogy Design Review Protocol | C8: Client deliverable | D8: SQ6 Content & Authoring | E8: P2 | I8: =COUNTIFS('Master Checklist'!$B:$B,$A8,'Master Checklist'!$D:$D,"Build") -> 13 | J8: =COUNTIFS('Master Checklist'!$B:$B,$A8,'Master Checklist'!$D:$D,"Test") -> 0 | K8: =COUNTIF('Master Checklist'!$B:$B,$A8) -> 13 | L8: Stage 0–4 | M8: =COUNTIFS('Master Checklist'!$B:$B,$A8,'Master Checklist'!$Y:$Y,"Done") -> 0 | N8: =IF(K8=0,0,M8/K8) -> 0 | O8: =COUNTIFS('Master Checklist'!$B:$B,$A8,'Master Checklist'!$Y:$Y,"Blocked") -> 0
A9: D05 | B9: TLA CMM Level 2 — Microservices | C9: Client deliverable | D9: SQ4 TLA & Federation | E9: M21 | I9: =COUNTIFS('Master Checklist'!$B:$B,$A9,'Master Checklist'!$D:$D,"Build") -> 8 | J9: =COUNTIFS('Master Checklist'!$B:$B,$A9,'Master Checklist'!$D:$D,"Test") -> 5 | K9: =COUNTIF('Master Checklist'!$B:$B,$A9) -> 13 | L9: Stage 1–5 | M9: =COUNTIFS('Master Checklist'!$B:$B,$A9,'Master Checklist'!$Y:$Y,"Done") -> 0 | N9: =IF(K9=0,0,M9/K9) -> 0 | O9: =COUNTIFS('Master Checklist'!$B:$B,$A9,'Master Checklist'!$Y:$Y,"Blocked") -> 0
A10: D06 | B10: TLA Experience-Index (ELRR) | C10: Client deliverable | D10: SQ4 TLA & Federation | E10: M17 | I10: =COUNTIFS('Master Checklist'!$B:$B,$A10,'Master Checklist'!$D:$D,"Build") -> 29 | J10: =COUNTIFS('Master Checklist'!$B:$B,$A10,'Master Checklist'!$D:$D,"Test") -> 7 | K10: =COUNTIF('Master Checklist'!$B:$B,$A10) -> 36 | L10: Stage 0–3 | M10: =COUNTIFS('Master Checklist'!$B:$B,$A10,'Master Checklist'!$Y:$Y,"Done") -> 0 | N10: =IF(K10=0,0,M10/K10) -> 0 | O10: =COUNTIFS('Master Checklist'!$B:$B,$A10,'Master Checklist'!$Y:$Y,"Blocked") -> 0
A11: D07 | B11: TLA Course Catalogue (ECC) | C11: Client deliverable | D11: SQ4 TLA & Federation | E11: M18 | I11: =COUNTIFS('Master Checklist'!$B:$B,$A11,'Master Checklist'!$D:$D,"Build") -> 26 | J11: =COUNTIFS('Master Checklist'!$B:$B,$A11,'Master Checklist'!$D:$D,"Test") -> 6 | K11: =COUNTIF('Master Checklist'!$B:$B,$A11) -> 32 | L11: Stage 0–2 | M11: =COUNTIFS('Master Checklist'!$B:$B,$A11,'Master Checklist'!$Y:$Y,"Done") -> 0 | N11: =IF(K11=0,0,M11/K11) -> 0 | O11: =COUNTIFS('Master Checklist'!$B:$B,$A11,'Master Checklist'!$Y:$Y,"Blocked") -> 0
A12: D08 | B12: TLA Competency-Registry | C12: Client deliverable | D12: SQ4 TLA & Federation | E12: M19 | I12: =COUNTIFS('Master Checklist'!$B:$B,$A12,'Master Checklist'!$D:$D,"Build") -> 55 | J12: =COUNTIFS('Master Checklist'!$B:$B,$A12,'Master Checklist'!$D:$D,"Test") -> 7 | K12: =COUNTIF('Master Checklist'!$B:$B,$A12) -> 62 | L12: Stage 0–2 | M12: =COUNTIFS('Master Checklist'!$B:$B,$A12,'Master Checklist'!$Y:$Y,"Done") -> 0 | N12: =IF(K12=0,0,M12/K12) -> 0 | O12: =COUNTIFS('Master Checklist'!$B:$B,$A12,'Master Checklist'!$Y:$Y,"Blocked") -> 0
A13: D09 | B13: TLA CMM Level 3 | C13: Client deliverable | D13: SQ4 TLA & Federation | E13: M21 | I13: =COUNTIFS('Master Checklist'!$B:$B,$A13,'Master Checklist'!$D:$D,"Build") -> 4 | J13: =COUNTIFS('Master Checklist'!$B:$B,$A13,'Master Checklist'!$D:$D,"Test") -> 1 | K13: =COUNTIF('Master Checklist'!$B:$B,$A13) -> 5 | L13: Stage 4–5 | M13: =COUNTIFS('Master Checklist'!$B:$B,$A13,'Master Checklist'!$Y:$Y,"Done") -> 0 | N13: =IF(K13=0,0,M13/K13) -> 0 | O13: =COUNTIFS('Master Checklist'!$B:$B,$A13,'Master Checklist'!$Y:$Y,"Blocked") -> 0
A14: D10 | B14: PDFs & Technical Manuals Integration — Live TO Connection | C14: Client deliverable | D14: SQ6 Content & Authoring | E14: M25 | I14: =COUNTIFS('Master Checklist'!$B:$B,$A14,'Master Checklist'!$D:$D,"Build") -> 26 | J14: =COUNTIFS('Master Checklist'!$B:$B,$A14,'Master Checklist'!$D:$D,"Test") -> 6 | K14: =COUNTIF('Master Checklist'!$B:$B,$A14) -> 32 | L14: Stage 0–3 | M14: =COUNTIFS('Master Checklist'!$B:$B,$A14,'Master Checklist'!$Y:$Y,"Done") -> 0 | N14: =IF(K14=0,0,M14/K14) -> 0 | O14: =COUNTIFS('Master Checklist'!$B:$B,$A14,'Master Checklist'!$Y:$Y,"Blocked") -> 0
A15: D11 | B15: DCT — Content Authoring & Lesson Planner | C15: Client deliverable | D15: SQ6 Content & Authoring | E15: M22 | I15: =COUNTIFS('Master Checklist'!$B:$B,$A15,'Master Checklist'!$D:$D,"Build") -> 38 | J15: =COUNTIFS('Master Checklist'!$B:$B,$A15,'Master Checklist'!$D:$D,"Test") -> 6 | K15: =COUNTIF('Master Checklist'!$B:$B,$A15) -> 44 | L15: Stage 0–2 | M15: =COUNTIFS('Master Checklist'!$B:$B,$A15,'Master Checklist'!$Y:$Y,"Done") -> 0 | N15: =IF(K15=0,0,M15/K15) -> 0 | O15: =COUNTIFS('Master Checklist'!$B:$B,$A15,'Master Checklist'!$Y:$Y,"Blocked") -> 0
A16: D12 | B16: Interactive eBooks — Technical Manuals Digitization | C16: Client deliverable | D16: SQ6 Content & Authoring | E16: M9, M24, SVC | I16: =COUNTIFS('Master Checklist'!$B:$B,$A16,'Master Checklist'!$D:$D,"Build") -> 62 | J16: =COUNTIFS('Master Checklist'!$B:$B,$A16,'Master Checklist'!$D:$D,"Test") -> 14 | K16: =COUNTIF('Master Checklist'!$B:$B,$A16) -> 76 | L16: Stage 0–3 | M16: =COUNTIFS('Master Checklist'!$B:$B,$A16,'Master Checklist'!$Y:$Y,"Done") -> 0 | N16: =IF(K16=0,0,M16/K16) -> 0 | O16: =COUNTIFS('Master Checklist'!$B:$B,$A16,'Master Checklist'!$Y:$Y,"Blocked") -> 0
A17: D13 | B17: SME Chatbot — Content Authoring Support | C17: Client deliverable | D17: SQ5 AI & Assessment | E17: M23 | I17: =COUNTIFS('Master Checklist'!$B:$B,$A17,'Master Checklist'!$D:$D,"Build") -> 14 | J17: =COUNTIFS('Master Checklist'!$B:$B,$A17,'Master Checklist'!$D:$D,"Test") -> 6 | K17: =COUNTIF('Master Checklist'!$B:$B,$A17) -> 20 | L17: Stage 0–3 | M17: =COUNTIFS('Master Checklist'!$B:$B,$A17,'Master Checklist'!$Y:$Y,"Done") -> 0 | N17: =IF(K17=0,0,M17/K17) -> 0 | O17: =COUNTIFS('Master Checklist'!$B:$B,$A17,'Master Checklist'!$Y:$Y,"Blocked") -> 0
A18: D14 | B18: Personalized Learning Engine — Core | C18: Client deliverable | D18: SQ2 Learning Tools | E18: M11, M13, M28 | I18: =COUNTIFS('Master Checklist'!$B:$B,$A18,'Master Checklist'!$D:$D,"Build") -> 101 | J18: =COUNTIFS('Master Checklist'!$B:$B,$A18,'Master Checklist'!$D:$D,"Test") -> 20 | K18: =COUNTIF('Master Checklist'!$B:$B,$A18) -> 121 | L18: Stage 0–4 | M18: =COUNTIFS('Master Checklist'!$B:$B,$A18,'Master Checklist'!$Y:$Y,"Done") -> 0 | N18: =IF(K18=0,0,M18/K18) -> 0 | O18: =COUNTIFS('Master Checklist'!$B:$B,$A18,'Master Checklist'!$Y:$Y,"Blocked") -> 0
A19: D15 | B19: Competency Assessment Tool | C19: Client deliverable | D19: SQ2 Learning Tools | E19: M12, M29 | I19: =COUNTIFS('Master Checklist'!$B:$B,$A19,'Master Checklist'!$D:$D,"Build") -> 53 | J19: =COUNTIFS('Master Checklist'!$B:$B,$A19,'Master Checklist'!$D:$D,"Test") -> 13 | K19: =COUNTIF('Master Checklist'!$B:$B,$A19) -> 66 | L19: Stage 0–3 | M19: =COUNTIFS('Master Checklist'!$B:$B,$A19,'Master Checklist'!$Y:$Y,"Done") -> 0 | N19: =IF(K19=0,0,M19/K19) -> 0 | O19: =COUNTIFS('Master Checklist'!$B:$B,$A19,'Master Checklist'!$Y:$Y,"Blocked") -> 0
A20: D16 | B20: TLA Profile Management — Initial Deployment | C20: Client deliverable | D20: SQ4 TLA & Federation | E20: M20 | I20: =COUNTIFS('Master Checklist'!$B:$B,$A20,'Master Checklist'!$D:$D,"Build") -> 23 | J20: =COUNTIFS('Master Checklist'!$B:$B,$A20,'Master Checklist'!$D:$D,"Test") -> 6 | K20: =COUNTIF('Master Checklist'!$B:$B,$A20) -> 29 | L20: Stage 2–3 | M20: =COUNTIFS('Master Checklist'!$B:$B,$A20,'Master Checklist'!$Y:$Y,"Done") -> 0 | N20: =IF(K20=0,0,M20/K20) -> 0 | O20: =COUNTIFS('Master Checklist'!$B:$B,$A20,'Master Checklist'!$Y:$Y,"Blocked") -> 0
A21: D17 | B21: Cross-Organisation / Cross-Command Data Pipeline | C21: Client deliverable | D21: SQ4 TLA & Federation | E21: M31 | I21: =COUNTIFS('Master Checklist'!$B:$B,$A21,'Master Checklist'!$D:$D,"Build") -> 78 | J21: =COUNTIFS('Master Checklist'!$B:$B,$A21,'Master Checklist'!$D:$D,"Test") -> 7 | K21: =COUNTIF('Master Checklist'!$B:$B,$A21) -> 85 | L21: Stage 0–5 | M21: =COUNTIFS('Master Checklist'!$B:$B,$A21,'Master Checklist'!$Y:$Y,"Done") -> 0 | N21: =IF(K21=0,0,M21/K21) -> 0 | O21: =COUNTIFS('Master Checklist'!$B:$B,$A21,'Master Checklist'!$Y:$Y,"Blocked") -> 0 | P21: was: Cross-Command Data Pipeline
A22: D18 | B22: Analytics Dashboard Suite (incl. TLA) — All Roles | C22: Client deliverable | D22: SQ3 Data & Analytics | E22: M6, M10, M30 | I22: =COUNTIFS('Master Checklist'!$B:$B,$A22,'Master Checklist'!$D:$D,"Build") -> 201 | J22: =COUNTIFS('Master Checklist'!$B:$B,$A22,'Master Checklist'!$D:$D,"Test") -> 19 | K22: =COUNTIF('Master Checklist'!$B:$B,$A22) -> 220 | L22: Stage 0–5 | M22: =COUNTIFS('Master Checklist'!$B:$B,$A22,'Master Checklist'!$Y:$Y,"Done") -> 0 | N22: =IF(K22=0,0,M22/K22) -> 0 | O22: =COUNTIFS('Master Checklist'!$B:$B,$A22,'Master Checklist'!$Y:$Y,"Blocked") -> 0
A23: D19 | B23: XR Store App — Android & Windows | C23: Client deliverable | D23: SQ7 Field & Immersive | E23: M16, M32, SVC | I23: =COUNTIFS('Master Checklist'!$B:$B,$A23,'Master Checklist'!$D:$D,"Build") -> 69 | J23: =COUNTIFS('Master Checklist'!$B:$B,$A23,'Master Checklist'!$D:$D,"Test") -> 12 | K23: =COUNTIF('Master Checklist'!$B:$B,$A23) -> 81 | L23: Stage 0–4 | M23: =COUNTIFS('Master Checklist'!$B:$B,$A23,'Master Checklist'!$Y:$Y,"Done") -> 0 | N23: =IF(K23=0,0,M23/K23) -> 0 | O23: =COUNTIFS('Master Checklist'!$B:$B,$A23,'Master Checklist'!$Y:$Y,"Blocked") -> 0
A24: D20 | B24: Immersive Lab — Reference Site (India) | C24: Client deliverable | D24: SQ7 Field & Immersive | E24: M33, SVC | I24: =COUNTIFS('Master Checklist'!$B:$B,$A24,'Master Checklist'!$D:$D,"Build") -> 59 | J24: =COUNTIFS('Master Checklist'!$B:$B,$A24,'Master Checklist'!$D:$D,"Test") -> 7 | K24: =COUNTIF('Master Checklist'!$B:$B,$A24) -> 66 | L24: Stage 3–4 | M24: =COUNTIFS('Master Checklist'!$B:$B,$A24,'Master Checklist'!$Y:$Y,"Done") -> 0 | N24: =IF(K24=0,0,M24/K24) -> 0 | O24: =COUNTIFS('Master Checklist'!$B:$B,$A24,'Master Checklist'!$Y:$Y,"Blocked") -> 0 | P24: was: Hardware Immersive Labs — Site A (Barksdale AFB)
A25: D21 | B25: Immersive Lab — Replication Site (India) | C25: Client deliverable | D25: SQ7 Field & Immersive | E25: M34 | I25: =COUNTIFS('Master Checklist'!$B:$B,$A25,'Master Checklist'!$D:$D,"Build") -> 22 | J25: =COUNTIFS('Master Checklist'!$B:$B,$A25,'Master Checklist'!$D:$D,"Test") -> 6 | K25: =COUNTIF('Master Checklist'!$B:$B,$A25) -> 28 | L25: Stage 5–5 | M25: =COUNTIFS('Master Checklist'!$B:$B,$A25,'Master Checklist'!$Y:$Y,"Done") -> 0 | N25: =IF(K25=0,0,M25/K25) -> 0 | O25: =COUNTIFS('Master Checklist'!$B:$B,$A25,'Master Checklist'!$Y:$Y,"Blocked") -> 0 | P25: was: Hardware Immersive Labs — Site B (Minot AFB)
A26: D22 | B26: AI/ML Procedural Walkthrough Engine | C26: Client deliverable | D26: SQ7 Field & Immersive | E26: M35 | I26: =COUNTIFS('Master Checklist'!$B:$B,$A26,'Master Checklist'!$D:$D,"Build") -> 27 | J26: =COUNTIFS('Master Checklist'!$B:$B,$A26,'Master Checklist'!$D:$D,"Test") -> 7 | K26: =COUNTIF('Master Checklist'!$B:$B,$A26) -> 34 | L26: Stage 0–4 | M26: =COUNTIFS('Master Checklist'!$B:$B,$A26,'Master Checklist'!$Y:$Y,"Done") -> 0 | N26: =IF(K26=0,0,M26/K26) -> 0 | O26: =COUNTIFS('Master Checklist'!$B:$B,$A26,'Master Checklist'!$Y:$Y,"Blocked") -> 0
A27: D23 | B27: Difference Training Application | C27: Client deliverable | D27: SQ2 Learning Tools | E27: M14, M36 | I27: =COUNTIFS('Master Checklist'!$B:$B,$A27,'Master Checklist'!$D:$D,"Build") -> 49 | J27: =COUNTIFS('Master Checklist'!$B:$B,$A27,'Master Checklist'!$D:$D,"Test") -> 12 | K27: =COUNTIF('Master Checklist'!$B:$B,$A27) -> 61 | L27: Stage 0–4 | M27: =COUNTIFS('Master Checklist'!$B:$B,$A27,'Master Checklist'!$Y:$Y,"Done") -> 0 | N27: =IF(K27=0,0,M27/K27) -> 0 | O27: =COUNTIFS('Master Checklist'!$B:$B,$A27,'Master Checklist'!$Y:$Y,"Blocked") -> 0
A28: D24 | B28: Microlearning Mobile Application | C28: Client deliverable | D28: SQ7 Field & Immersive | E28: M37, SVC | I28: =COUNTIFS('Master Checklist'!$B:$B,$A28,'Master Checklist'!$D:$D,"Build") -> 18 | J28: =COUNTIFS('Master Checklist'!$B:$B,$A28,'Master Checklist'!$D:$D,"Test") -> 6 | K28: =COUNTIF('Master Checklist'!$B:$B,$A28) -> 24 | L28: Stage 2–4 | M28: =COUNTIFS('Master Checklist'!$B:$B,$A28,'Master Checklist'!$Y:$Y,"Done") -> 0 | N28: =IF(K28=0,0,M28/K28) -> 0 | O28: =COUNTIFS('Master Checklist'!$B:$B,$A28,'Master Checklist'!$Y:$Y,"Blocked") -> 0
A29: D25 | B29: Accelerate Upgrade Readiness Measurement Plan | C29: Client deliverable | D29: SQ8 Program & Governance | E29: P3 | I29: =COUNTIFS('Master Checklist'!$B:$B,$A29,'Master Checklist'!$D:$D,"Build") -> 21 | J29: =COUNTIFS('Master Checklist'!$B:$B,$A29,'Master Checklist'!$D:$D,"Test") -> 0 | K29: =COUNTIF('Master Checklist'!$B:$B,$A29) -> 21 | L29: Stage 0–5 | M29: =COUNTIFS('Master Checklist'!$B:$B,$A29,'Master Checklist'!$Y:$Y,"Done") -> 0 | N29: =IF(K29=0,0,M29/K29) -> 0 | O29: =COUNTIFS('Master Checklist'!$B:$B,$A29,'Master Checklist'!$Y:$Y,"Blocked") -> 0
A30: D26 | B30: Measure of Operational Effectiveness (MOE) AR Application | C30: Client deliverable | D30: SQ7 Field & Immersive | E30: M38 | I30: =COUNTIFS('Master Checklist'!$B:$B,$A30,'Master Checklist'!$D:$D,"Build") -> 16 | J30: =COUNTIFS('Master Checklist'!$B:$B,$A30,'Master Checklist'!$D:$D,"Test") -> 6 | K30: =COUNTIF('Master Checklist'!$B:$B,$A30) -> 22 | L30: Stage 3–4 | M30: =COUNTIFS('Master Checklist'!$B:$B,$A30,'Master Checklist'!$Y:$Y,"Done") -> 0 | N30: =IF(K30=0,0,M30/K30) -> 0 | O30: =COUNTIFS('Master Checklist'!$B:$B,$A30,'Master Checklist'!$Y:$Y,"Blocked") -> 0
A31: D27 | B31: Train the Trainer — Embedded SME Service | C31: Client deliverable | D31: SQ8 Program & Governance | E31: P4 | I31: =COUNTIFS('Master Checklist'!$B:$B,$A31,'Master Checklist'!$D:$D,"Build") -> 11 | J31: =COUNTIFS('Master Checklist'!$B:$B,$A31,'Master Checklist'!$D:$D,"Test") -> 0 | K31: =COUNTIF('Master Checklist'!$B:$B,$A31) -> 11 | L31: Stage 2–5 | M31: =COUNTIFS('Master Checklist'!$B:$B,$A31,'Master Checklist'!$Y:$Y,"Done") -> 0 | N31: =IF(K31=0,0,M31/K31) -> 0 | O31: =COUNTIFS('Master Checklist'!$B:$B,$A31,'Master Checklist'!$Y:$Y,"Blocked") -> 0
A32: D28 | B32: TLA CMM Level 5 — Enterprise Competency Mapping | C32: Client deliverable | D32: SQ4 TLA & Federation | E32: M21 | I32: =COUNTIFS('Master Checklist'!$B:$B,$A32,'Master Checklist'!$D:$D,"Build") -> 2 | J32: =COUNTIFS('Master Checklist'!$B:$B,$A32,'Master Checklist'!$D:$D,"Test") -> 0 | K32: =COUNTIF('Master Checklist'!$B:$B,$A32) -> 2 | L32: Stage 1–5 | M32: =COUNTIFS('Master Checklist'!$B:$B,$A32,'Master Checklist'!$Y:$Y,"Done") -> 0 | N32: =IF(K32=0,0,M32/K32) -> 0 | O32: =COUNTIFS('Master Checklist'!$B:$B,$A32,'Master Checklist'!$Y:$Y,"Blocked") -> 0
A33: D29 | B33: Full Multiverse Platform Integration & Acceptance | C33: Client deliverable | D33: SQ8 Program & Governance | E33: P5 | I33: =COUNTIFS('Master Checklist'!$B:$B,$A33,'Master Checklist'!$D:$D,"Build") -> 22 | J33: =COUNTIFS('Master Checklist'!$B:$B,$A33,'Master Checklist'!$D:$D,"Test") -> 0 | K33: =COUNTIF('Master Checklist'!$B:$B,$A33) -> 22 | L33: Stage 0–5 | M33: =COUNTIFS('Master Checklist'!$B:$B,$A33,'Master Checklist'!$Y:$Y,"Done") -> 0 | N33: =IF(K33=0,0,M33/K33) -> 0 | O33: =COUNTIFS('Master Checklist'!$B:$B,$A33,'Master Checklist'!$Y:$Y,"Blocked") -> 0
A34: D30 | B34: Final Report | C34: Client deliverable | D34: SQ8 Program & Governance | E34: P6 | I34: =COUNTIFS('Master Checklist'!$B:$B,$A34,'Master Checklist'!$D:$D,"Build") -> 10 | J34: =COUNTIFS('Master Checklist'!$B:$B,$A34,'Master Checklist'!$D:$D,"Test") -> 0 | K34: =COUNTIF('Master Checklist'!$B:$B,$A34) -> 10 | L34: Stage 1–5 | M34: =COUNTIFS('Master Checklist'!$B:$B,$A34,'Master Checklist'!$Y:$Y,"Done") -> 0 | N34: =IF(K34=0,0,M34/K34) -> 0 | O34: =COUNTIFS('Master Checklist'!$B:$B,$A34,'Master Checklist'!$Y:$Y,"Blocked") -> 0
A35: E01 | B35: Core Platform, Identity & Shared Services (enabler) | C35: Enabling platform | D35: SQ1 Platform Core | E35: M1, M4, SVC | I35: =COUNTIFS('Master Checklist'!$B:$B,$A35,'Master Checklist'!$D:$D,"Build") -> 143 | J35: =COUNTIFS('Master Checklist'!$B:$B,$A35,'Master Checklist'!$D:$D,"Test") -> 13 | K35: =COUNTIF('Master Checklist'!$B:$B,$A35) -> 156 | L35: Stage 0–3 | M35: =COUNTIFS('Master Checklist'!$B:$B,$A35,'Master Checklist'!$Y:$Y,"Done") -> 0 | N35: =IF(K35=0,0,M35/K35) -> 0 | O35: =COUNTIFS('Master Checklist'!$B:$B,$A35,'Master Checklist'!$Y:$Y,"Blocked") -> 0
A36: E02 | B36: Learning Records Spine — LRS + Learning-data API (enabler) | C36: Enabling platform | D36: SQ1 Platform Core | E36: M2, M3 | I36: =COUNTIFS('Master Checklist'!$B:$B,$A36,'Master Checklist'!$D:$D,"Build") -> 72 | J36: =COUNTIFS('Master Checklist'!$B:$B,$A36,'Master Checklist'!$D:$D,"Test") -> 14 | K36: =COUNTIF('Master Checklist'!$B:$B,$A36) -> 86 | L36: Stage 0–1 | M36: =COUNTIFS('Master Checklist'!$B:$B,$A36,'Master Checklist'!$Y:$Y,"Done") -> 0 | N36: =IF(K36=0,0,M36/K36) -> 0 | O36: =COUNTIFS('Master Checklist'!$B:$B,$A36,'Master Checklist'!$Y:$Y,"Blocked") -> 0
A37: E03 | B37: LMS & Course-Site Integration — LTI 1.3 (enabler) | C37: Enabling platform | D37: SQ2 Learning Tools | E37: M5, M7 | I37: =COUNTIFS('Master Checklist'!$B:$B,$A37,'Master Checklist'!$D:$D,"Build") -> 65 | J37: =COUNTIFS('Master Checklist'!$B:$B,$A37,'Master Checklist'!$D:$D,"Test") -> 13 | K37: =COUNTIF('Master Checklist'!$B:$B,$A37) -> 78 | L37: Stage 0–3 | M37: =COUNTIFS('Master Checklist'!$B:$B,$A37,'Master Checklist'!$Y:$Y,"Done") -> 0 | N37: =IF(K37=0,0,M37/K37) -> 0 | O37: =COUNTIFS('Master Checklist'!$B:$B,$A37,'Master Checklist'!$Y:$Y,"Blocked") -> 0
... A47: E13 | B47: Internal Enablement & Knowledge Continuity | C47: Enabling programme | D47: SQ8 Program & Governance | E47: SVC | I47: =COUNTIFS('Master Checklist'!$B:$B,$A47,'Master Checklist'!$D:$D,"Build") -> 12 | J47: =COUNTIFS('Master Checklist'!$B:$B,$A47,'Master Checklist'!$D:$D,"Test") -> 0 | K47: =COUNTIF('Master Checklist'!$B:$B,$A47) -> 12 | L47: Stage 1–5 | M47: =COUNTIFS('Master Checklist'!$B:$B,$A47,'Master Checklist'!$Y:$Y,"Done") -> 0 | N47: =IF(K47=0,0,M47/K47) -> 0 | O47: =COUNTIFS('Master Checklist'!$B:$B,$A47,'Master Checklist'!$Y:$Y,"Blocked") -> 0
B48: TOTAL | I48: =SUM(I5:I47) -> 1795 | J48: =SUM(J5:J47) -> 325 | K48: =SUM(K5:K47) -> 2120 | M48: =SUM(M5:M47) -> 0 | O48: =SUM(O5:O47) -> 0

Sheet Master Checklist
A1: ID | B1: ProductID | C1: Product | D1: WorkType | E1: Priority | F1: Category | G1: Module | H1: Squad | I1: OwnerRole | J1: TestTeam | K1: TestCaseID | L1: Assignee | M1: EstDays | N1: TargetSprint | O1: Stage | P1: Task | Q1: Subtask | R1: Item | S1: DependsOn | T1: Evidence | U1: EvidenceLink | V1: AcceptanceCriterion | W1: DeploymentClass | X1: SourceRef | Y1: Status | Z1: Waiver | AA1: LastUpdated | AB1: SeqFlag | AC1: Notes
A2: FND-01.1.01 | B2: E01 | C2: Core Platform, Identity & Shared Services (enabler) | D2: Build | E2: P1 | F2: FND | G2: M1 | H2: SQ1 Platform Core | I2: Platform Architect | J2: — | O2: 0 | P2: M1 identity contracts | Q2: Tenancy and token contract | R2: Tenancy decision record written (realm-per-tenant vs single realm with tenant claims) covering token contents, session behavior, admin tooling, and onboarding cost, and approved by architecture board | S2: - | T2: Signed decision record in decision register | V2: Decision record merged with named approver and date | W2: All | X2: Review D-M1 gap; MOD-008 | Y2: Not started
A3: FND-01.1.02 | B3: E01 | C3: Core Platform, Identity & Shared Services (enabler) | D3: Build | E3: P0 | F3: FND | G3: M1 | H3: SQ1 Platform Core | I3: Platform Architect | J3: — | O3: 0 | P3: M1 identity contracts | Q3: Tenancy and token contract | R3: Token claim schema defined (tenant ID, command ID, roles, audience, per-service scopes) and issued as versioned contract document | S3: FND-01.1.01 | T3: Claim schema v1 in contract repo | V3: Schema validates sample tokens for 3 personas plus 1 service account without ambiguity | W3: All | X3: Review G.4; HS-11 | Y3: Not started
A4: FND-01.1.03 | B4: E01 | C4: Core Platform, Identity & Shared Services (enabler) | D4: Build | E4: P1 | F4: FND | G4: M1 | H4: SQ1 Platform Core | I4: Platform Architect | J4: — | O4: 0 | P4: M1 identity contracts | Q4: Tenancy and token contract | R4: Token lifecycle policy documented: access/refresh lifetimes, revocation propagation SLA, signing-key rotation schedule, offline-device credential rules | S4: FND-01.1.02 | T4: Token lifecycle policy doc | V4: Policy states numeric lifetime, SLA, and rotation interval for every token type; approved | W4: All | X4: Review D-M1 token lifecycle gap | Y4: Not started
A5: FND-01.1.04 | B5: E01 | C5: Core Platform, Identity & Shared Services (enabler) | D5: Build | E5: P1 | F5: FND | G5: M1 | H5: SQ1 Platform Core | I5: Platform Architect | J5: — | O5: 0 | P5: M1 identity contracts | Q5: Tenancy and token contract | R5: Role precedence rule between Keycloak roles and LTI launch roles documented with M1 as owner and M7 as read-only consumer | S5: - | T5: Role precedence rule doc referenced by M7 spec | V5: Rule resolves the teacher-in-Moodle/student-in-Keycloak case deterministically; COR team acknowledged | W5: All | X5: Review D-M1 [CONTRADICTED] role truth | Y5: Not started
A6: FND-01.1.05 | B6: E01 | C6: Core Platform, Identity & Shared Services (enabler) | D6: Build | E6: P1 | F6: FND | G6: M1 | H6: SQ1 Platform Core | I6: Platform Architect | J6: — | O6: 0 | P6: M1 identity contracts | Q6: Tenancy and token contract | R6: Tenant-resolution contract defined for the shared middleware/library consumed by all modules (claim parsing, missing-claim rejection, audited denial format) | S6: FND-01.1.02 | T6: Tenant-resolution contract v1 | V6: Contract specifies behavior for present, missing, and malformed tenant claims; reject-by-default | W6: All | X6: MOD-008 | Y6: Not started
A7: FND-01.1.06 | B7: E01 | C7: Core Platform, Identity & Shared Services (enabler) | D7: Build | E7: P1 | F7: FND | G7: M1 | H7: SQ1 Platform Core | I7: Platform Architect | J7: — | O7: 0 | P7: M1 identity contracts | Q7: Tenancy and token contract | R7: Service-to-service authentication model defined: machine identity per module, client-credentials or mTLS, least-privilege scopes, no all-tenant service tokens | S7: FND-01.1.02 | T7: Service-auth model doc listing every Slice A service identity | V7: Every Slice A module has a named machine identity with an explicit scope list; zero wildcard-tenant scopes | W7: All | X7: R-sec-G (G.4 service auth absent) | Y7: Not started
A8: FND-01.2.01 | B8: E01 | C8: Core Platform, Identity & Shared Services (enabler) | D8: Build | E8: P0 | F8: FND | G8: M1 | H8: SQ1 Platform Core | I8: Platform Architect | J8: — | O8: 0 | P8: M1 identity contracts | Q8: Publication and conformance | R8: Identity contracts (token claims, tenant resolution, service auth) published to the contract registry with semver | S8: FND-01.1.02, FND-13.1.01 | T8: Registry entries with version tags | V8: All three contracts retrievable from registry at v1.0.0 | W8: All | X8: HS-11; PLAN M1 main-jobs | Y8: Not started
A9: FND-01.2.02 | B9: E01 | C9: Core Platform, Identity & Shared Services (enabler) | D9: Build | E9: P1 | F9: FND | G9: M1 | H9: SQ1 Platform Core | I9: QA Engineer | J9: — | O9: 0 | P9: M1 identity contracts | Q9: Publication and conformance | R9: Token conformance test suite written and green against a stub IdP in CI (valid, expired, missing tenant claim, wrong audience, revoked) | S9: FND-01.2.01 | T9: CI job run link | V9: All 5 case classes pass; suite blocks merge on failure | W9: All | X9: Stage 0 exit gate (Section T) | Y9: Not started
A10: FND-01.2.03 | B10: E01 | C10: Core Platform, Identity & Shared Services (enabler) | D10: Build | E10: P1 | F10: FND | G10: M1 | H10: SQ1 Platform Core | I10: QA Lead | J10: — | O10: 0 | P10: M1 identity contracts | Q10: Publication and conformance | R10: Exit-gate evidence bundle assembled and reviewed for M1 identity contracts task | S10: FND-01.2.02 | T10: Evidence bundle in program repo | V10: All task items evidenced; reviewer sign-off recorded | W10: All | X10: Brief mandatory lane | Y10: Not started
A11: FND-02.1.01 | B11: E01 | C11: Core Platform, Identity & Shared Services (enabler) | D11: Build | E11: P2 | F11: FND | G11: M1 | H11: SQ1 Platform Core | I11: DevSecOps Engineer | J11: — | O11: 1 | P11: Keycloak deployment | Q11: Realm and client provisioning | R11: Keycloak pinned version deployed via IaC with external PostgreSQL and HA replicas | S11: FND-01.1.01 | T11: IaC repo commit plus running environment | V11: Two Keycloak nodes serve logins; single-node kill causes no login failures in test | W11: All | X11: PLAN M1 main-jobs | Y11: Not started
A12: FND-02.1.02 | B12: E01 | C12: Core Platform, Identity & Shared Services (enabler) | D12: Build | E12: P2 | F12: FND | G12: M1 | H12: SQ1 Platform Core | I12: DevSecOps Engineer | J12: — | O12: 1 | P12: Keycloak deployment | Q12: Realm and client provisioning | R12: Tenant onboarding automation provisions a new tenant (realm or claims per decision record) in under 30 minutes | S12: FND-02.1.01 | T12: Automation script plus timed run log | V12: Fresh tenant provisioned end-to-end in one command in under 30 min | W12: All | X12: Review D-M1 exit criteria | Y12: Not started
A13: FND-02.1.03 | B13: E01 | C13: Core Platform, Identity & Shared Services (enabler) | D13: Build | E13: P2 | F13: FND | G13: M1 | H13: SQ1 Platform Core | I13: DevSecOps Engineer | J13: — | O13: 1 | P13: Keycloak deployment | Q13: Realm and client provisioning | R13: OIDC clients registered for M3, M5, M6, and M7 with per-client scopes and secrets stored in vault | S13: FND-02.1.01 | T13: Client inventory export | V13: Each client authenticates with only its declared scopes; secrets absent from git | W13: All | X13: PLAN M1 main-jobs | Y13: Not started
... A290: COR-14.3.02 | B290: D12 | C290: Interactive eBooks — Technical Manuals Digitization | D290: Build | E290: P2 | F290: COR | G290: M9 | H290: SQ2 Learning Tools | I290: QA Lead | J290: — | O290: 2 | P290: M9 data, security, operations, and handoff | Q290: Documentation | R290: Exit-gate evidence bundle assembled and reviewed for task COR-14 (M9 data, security, operations, and handoff) | S290: - | T290: Reviewed evidence bundle in program repository | V290: Bundle links evidence for every item in the task and review sign-off is recorded | W290: All | X290: LOOP 2 exit-gate rule | Y290: Not started
A291: SMT-01.1.01 | B291: D18 | C291: Analytics Dashboard Suite (incl. TLA) — All Roles | D291: Build | E291: P1 | F291: SMT | G291: M10 | H291: SQ2 Learning Tools | I291: Platform Architect | J291: — | O291: 0 | P291: M10 teacher-view layer on unified analytics | Q291: Scope and contracts | R291: M6/M10 merge responsibility matrix recorded: dashboard construction owned by ANA-05, M10 delivers the teacher-experience layer and embedding hooks only, with no duplicate aggregation logic | S291: ANA-05.1.01 | T291: Signed responsibility matrix | V291: Matrix assigns every dashboard and aggregation to exactly one owner and is approved by architecture board | W291: All | X291: Review D-M10 required-changes; MOD merge; K | Y291: Not started | AB291: REVIEW: depends on later-stage item
A292: SMT-01.1.02 | B292: D18 | C292: Analytics Dashboard Suite (incl. TLA) — All Roles | D292: Build | E292: P1 | F292: SMT | G292: M10 | H292: SQ2 Learning Tools | I292: Platform Architect | J292: — | O292: 0 | P292: M10 teacher-view layer on unified analytics | Q292: Scope and contracts | R292: Teacher-view freshness and performance SLO recorded: p95 at or below 2 s for a 2000-learner class at 500 concurrent teachers with data staleness displayed on every view | S292: SMT-01.1.01 | T292: SLO document in architecture repo | V292: SLO document approved with both numeric targets and the staleness-display requirement | W292: All | X292: Review D-M10 required-changes; Loop 10 | Y292: Not started
A293: SMT-01.1.03 | B293: D18 | C293: Analytics Dashboard Suite (incl. TLA) — All Roles | D293: Build | E293: P1 | F293: SMT | G293: M10 | H293: SQ2 Learning Tools | I293: Platform Architect | J293: — | O293: 0 | P293: M10 teacher-view layer on unified analytics | Q293: Scope and contracts | R293: Cache design document approved defining every cached number as strictly derived with source query, TTL, tenant-scoped key, and rebuild job so Redis loss is a latency event only | S293: SMT-01.1.01 | T293: Approved cache design doc | V293: Every planned cache entry lists all four attributes; no cached value lacks a rebuild path | W293: All | X293: Review D-M10 gap cache; R-027; LOOP 5 | Y293: Not started
A294: SMT-01.2.01 | B294: D18 | C294: Analytics Dashboard Suite (incl. TLA) — All Roles | D294: Build | E294: P2 | F294: SMT | G294: M10 | H294: SQ2 Learning Tools | I294: Frontend Engineer | J294: — | O294: 2 | P294: M10 teacher-view layer on unified analytics | Q294: Embedding hooks and teacher-specific views | R294: Teacher dashboard embedding implemented in course-site teacher views via M7 launch context resolving to ANA signed-embed URLs | S294: ANA-06.1.03, COR-01.1.01 | T294: Embed integration test through Moodle | V294: Teacher launch opens the ANA teacher pack inside the LMS with tenant scope from server-side JWT only | W294: All | X294: PLAN M10 main-jobs; ANA-06 | Y294: Not started
A295: SMT-01.2.02 | B295: D18 | C295: Analytics Dashboard Suite (incl. TLA) — All Roles | D295: Build | E295: P1 | F295: SMT | G295: M10 | H295: SQ2 Learning Tools | I295: Frontend Engineer | J295: — | O295: 2 | P295: M10 teacher-view layer on unified analytics | Q295: Embedding hooks and teacher-specific views | R295: At-risk drill-down handoff implemented: teacher view links each flag to the M11 explanation panel showing factors, confidence, and data-completeness | S295: SMT-03.2.04, ANA-05.1.05 | T295: Drill-down E2E test | V295: Clicking a fixture flag renders factors, confidence, and completeness values matching engine output | W295: All | X295: PLAN M10; Review D-M11; Scenario 5 | Y295: Not started
A296: SMT-01.2.03 | B296: D18 | C296: Analytics Dashboard Suite (incl. TLA) — All Roles | D296: Build | E296: P1 | F296: SMT | G296: M10 | H296: SQ2 Learning Tools | I296: Frontend Engineer | J296: — | O296: 2 | P296: M10 teacher-view layer on unified analytics | Q296: Embedding hooks and teacher-specific views | R296: Undelivered-grades panel embedded in the teacher view fed by the M7 reconciliation feed | S296: COR-03.2.02 | T296: Panel E2E test | V296: Seeded failed passback appears in the teacher panel within 5 minutes | W296: All | X296: Scenario 3 required-change c | Y296: Not started
A297: SMT-01.2.04 | B297: D18 | C297: Analytics Dashboard Suite (incl. TLA) — All Roles | D297: Build | E297: P2 | F297: SMT | G297: M10 | H297: SQ2 Learning Tools | I297: Frontend Engineer | J297: — | O297: 2 | P297: M10 teacher-view layer on unified analytics | Q297: Embedding hooks and teacher-specific views | R297: Teacher export hook implemented delegating to the ANA governed export path with no separate M10 export pipeline | S297: SMT-01.2.01 | T297: Export hook code review plus test | V297: Export produced via ANA path with export audit log entry; no M10-local export code exists | W297: All | X297: PLAN M10 main-jobs; ANA-07 | Y297: Not started
A298: SMT-01.3.01 | B298: D18 | C298: Analytics Dashboard Suite (incl. TLA) — All Roles | D298: Build | E298: P2 | F298: SMT | G298: M10 | H298: SQ2 Learning Tools | I298: Backend Engineer | J298: — | O298: 2 | P298: M10 teacher-view layer on unified analytics | Q298: Cache build and validation | R298: Tenant-scoped cache keys implemented for all teacher-view cached numbers per the cache design | S298: SMT-01.1.03 | T298: Cache key implementation plus review | V298: Every cache key contains the tenant ID segment; static analysis finds zero unscoped keys | W298: All | X298: LOOP 8 cache tenancy; Review D-M10 | Y298: Not started
A299: SMT-01.3.02 | B299: D18 | C299: Analytics Dashboard Suite (incl. TLA) — All Roles | D299: Build | E299: P1 | F299: SMT | G299: M10 | H299: SQ2 Learning Tools | I299: QA Engineer | J299: — | O299: 2 | P299: M10 teacher-view layer on unified analytics | Q299: Cache build and validation | R299: Cache tenancy fuzz test executed: concurrent identical dashboard requests across tenants with zero cross-tenant cache hits | S299: SMT-01.3.01 | T299: Fuzz test report | V299: Zero cross-tenant hits across the full fuzz run | W299: All | X299: Review D-M10 tests; Scenario 2 | Y299: Not started
A300: SMT-01.3.03 | B300: D18 | C300: Analytics Dashboard Suite (incl. TLA) — All Roles | D300: Build | E300: P2 | F300: SMT | G300: M10 | H300: SQ2 Learning Tools | I300: Backend Engineer | J300: — | O300: 2 | P300: M10 teacher-view layer on unified analytics | Q300: Cache build and validation | R300: Cache rebuild job implemented and Redis FLUSHALL chaos test passed under load: views degrade to source reads or rebuilding states, numbers never change incorrectly, rebuild completes within SLO | S300: SMT-01.3.01 | T300: Chaos test report | V300: Zero incorrect numbers during flush recovery and rebuild inside the SLO window | W300: All | X300: Review D-M10 tests; R-027 | Y300: Not started
A301: SMT-01.3.04 | B301: D18 | C301: Analytics Dashboard Suite (incl. TLA) — All Roles | D301: Build | E301: P2 | F301: SMT | G301: M10 | H301: SQ2 Learning Tools | I301: QA Engineer | J301: — | O301: 2 | P301: M10 teacher-view layer on unified analytics | Q301: Cache build and validation | R301: Aggregate consistency check automated in CI: teacher-view aggregate equals mart-derived export for the same class and window exactly | S301: SMT-01.3.03, SMT-01.2.04 | T301: CI consistency job output | V301: Exact match on the fixture class across all compared aggregates in CI | W301: All | X301: Review D-M10 tests | Y301: Not started
A302: SMT-01.4.01 | B302: D18 | C302: Analytics Dashboard Suite (incl. TLA) — All Roles | D302: Build | E302: P2 | F302: SMT | G302: M10 | H302: SQ2 Learning Tools | I302: DevSecOps Engineer | J302: — | O302: 2 | P302: M10 teacher-view layer on unified analytics | Q302: Operations and handoff | R302: M10 observability implemented: embed load p95, cache hit ratio, and staleness age metrics with alerts and a runbook walked by a non-author | S302: SMT-01.2.01 | T302: Dashboards, alert rules, runbook sign-off | V302: All three metrics visible, alerts fired in test, and non-author completes the runbook walk | W302: All | X302: Review N; TST-STD 8 | Y302: Not started
A303: SMT-01.4.02 | B303: D18 | C303: Analytics Dashboard Suite (incl. TLA) — All Roles | D303: Build | E303: P1 | F303: SMT | G303: M10 | H303: SQ2 Learning Tools | I303: DevSecOps Engineer | J303: — | O303: 2 | P303: M10 teacher-view layer on unified analytics | Q303: Operations and handoff | R303: M10 teacher-view layer installed in the zero-egress enclave simulator against the enclave reporting replica with zero egress | S303: SMT-01.2.01 | T303: Enclave install log plus egress result | V303: Teacher views render from the enclave replica with zero outbound attempts | W303: Enclave | X303: MOD-015; A-014 | Y303: Not started
... A389: PER-03.1.04 | B389: D14 | C389: Personalized Learning Engine — Core | D389: Build | E389: P2 | F389: PER | G389: M13 | H389: SQ2 Learning Tools | I389: QA Engineer | J389: — | O389: 3 | P389: M13 data layer | Q389: Decision log and fixtures | R389: Decision-audit reconstruction test executed: for every path change in pilot fixtures, signal, rule version, and before/after path reconstructed from the log alone | S389: PER-03.1.01, PER-02.1.02 | T389: Reconstruction test report | V389: 100% of fixture path changes fully reconstructed | W389: All | X389: REV D1 M13 tests | Y389: Not started
A390: PER-03.1.05 | B390: D14 | C390: Personalized Learning Engine — Core | D390: Build | E390: P2 | F390: PER | G390: M13 | H390: SQ2 Learning Tools | I390: QA Lead | J390: — | O390: 2 | P390: M13 data layer | Q390: Decision log and fixtures | R390: Exit-gate evidence bundle assembled and reviewed for the M13 data task | S390: PER-03.1.04 | T390: Signed evidence bundle | V390: Bundle reviewed and signed by QA Lead | W390: All | X390: Brief exit-gate rule | Y390: Not started | AB390: REVIEW: depends on later-stage item
A391: PER-04.1.01 | B391: D14 | C391: Personalized Learning Engine — Core | D391: Build | E391: P2 | F391: PER | G391: M13 | H391: SQ2 Learning Tools | I391: Security Engineer | J391: — | O391: 3 | P391: M13 security | Q391: Authorization and audit | R391: Authorization negative tests passed: learner cannot read another learner's path; override restricted to instructor role | S391: PER-02.2.04 | T391: Negative test report | V391: Both negative tests green in CI | W391: All | X391: Brief lane 4 | Y391: Not started
A392: PER-04.1.02 | B392: D14 | C392: Personalized Learning Engine — Core | D392: Build | E392: P2 | F392: PER | G392: M13 | H392: SQ2 Learning Tools | I392: Backend Engineer | J392: — | O392: 3 | P392: M13 security | Q392: Authorization and audit | R392: Signal payload schema validation implemented with malformed-input rejection tests | S392: PER-01.1.01 | T392: Validation test report | V392: Malformed signals rejected with 4xx and logged; test green | W392: All | X392: Brief lane 4 | Y392: Not started
A393: PER-04.1.03 | B393: D14 | C393: Personalized Learning Engine — Core | D393: Build | E393: P1 | F393: PER | G393: M13 | H393: SQ2 Learning Tools | I393: Backend Engineer | J393: — | O393: 3 | P393: M13 security | Q393: Authorization and audit | R393: Path-change and override audit events emitted through the shared hash-chained audit service | S393: PLT-02.1.01 | T393: Audit query output | V393: Every path change and override retrievable from audit store | W393: All | X393: MOD-013 | Y393: Not started
A394: PER-04.1.04 | B394: D14 | C394: Personalized Learning Engine — Core | D394: Build | E394: P2 | F394: PER | G394: M13 | H394: SQ2 Learning Tools | I394: QA Lead | J394: — | O394: 3 | P394: M13 security | Q394: Authorization and audit | R394: Exit-gate evidence bundle assembled and reviewed for the M13 security task | S394: PER-04.1.03 | T394: Signed evidence bundle | V394: Bundle reviewed and signed by QA Lead | W394: All | X394: Brief exit-gate rule | Y394: Not started
A395: PER-05.1.01 | B395: D14 | C395: Personalized Learning Engine — Core | D395: Build | E395: P2 | F395: PER | G395: M13 | H395: SQ2 Learning Tools | I395: Backend Engineer | J395: — | O395: 3 | P395: M13 observability | Q395: Metrics alerts and SLO | R395: Structured logs with correlation IDs propagating from signal receipt to path decision | S395: PER-02.1.01 | T395: Log trace sample | V395: One correlation ID traces a signal to its path change end to end | W395: All | X395: Brief lane 5 | Y395: Not started
A396: PER-05.1.02 | B396: D14 | C396: Personalized Learning Engine — Core | D396: Build | E396: P2 | F396: PER | G396: M13 | H396: SQ2 Learning Tools | I396: Backend Engineer | J396: — | O396: 3 | P396: M13 observability | Q396: Metrics alerts and SLO | R396: Metrics dashboard live: path-change rate, override rate, oscillation-guard triggers, signal staleness | S396: PER-02.2.07 | T396: Dashboard URL | V396: All four metrics render with live data in staging | W396: All | X396: Brief lane 5 | Y396: Not started
A397: PER-05.1.03 | B397: D14 | C397: Personalized Learning Engine — Core | D397: Build | E397: P2 | F397: PER | G397: M13 | H397: SQ2 Learning Tools | I397: DevSecOps Engineer | J397: — | O397: 3 | P397: M13 observability | Q397: Metrics alerts and SLO | R397: Alerts configured for sequencing oscillation and signal-feed silence; runbook written and walked by a non-author | S397: PER-05.1.02 | T397: Alert config and runbook walkthrough record | V397: Both alerts fired in test; runbook walked by non-author | W397: All | X397: Brief lane 5 | Y397: Not started
A398: PER-05.1.04 | B398: D14 | C398: Personalized Learning Engine — Core | D398: Build | E398: P2 | F398: PER | G398: M13 | H398: SQ2 Learning Tools | I398: DevSecOps Engineer | J398: — | O398: 3 | P398: M13 observability | Q398: Metrics alerts and SLO | R398: Path-decision latency SLO defined and measured in staging | S398: PER-05.1.02 | T398: SLO document and staging measurement | V398: SLO documented; staging p95 within target | W398: All | X398: Brief lane 5 | Y398: Not started
A399: PER-05.1.05 | B399: D14 | C399: Personalized Learning Engine — Core | D399: Build | E399: P2 | F399: PER | G399: M13 | H399: SQ2 Learning Tools | I399: QA Lead | J399: — | O399: 3 | P399: M13 observability | Q399: Metrics alerts and SLO | R399: Exit-gate evidence bundle assembled and reviewed for the M13 observability task | S399: PER-05.1.04 | T399: Signed evidence bundle | V399: Bundle reviewed and signed by QA Lead | W399: All | X399: Brief exit-gate rule | Y399: Not started
A400: PER-06.1.01 | B400: D14 | C400: Personalized Learning Engine — Core | D400: Build | E400: P2 | F400: PER | G400: M13 | H400: SQ2 Learning Tools | I400: DevSecOps Engineer | J400: — | O400: 3 | P400: M13 deployment | Q400: CI and enclave install | R400: CI pipeline live: container build, contract conformance gate, unit and integration suites blocking | S400: PER-01.1.08 | T400: CI pipeline run | V400: Pipeline green and blocking on main branch | W400: All | X400: Brief lane 6 | Y400: Not started
A401: PER-06.1.02 | B401: D14 | C401: Personalized Learning Engine — Core | D401: Build | E401: P1 | F401: PER | G401: M13 | H401: SQ2 Learning Tools | I401: DevSecOps Engineer | J401: — | O401: 3 | P401: M13 deployment | Q401: CI and enclave install | R401: Enclave install from release bundle verified zero-egress: sequencing runs with no external calls | S401: PER-06.1.01 | T401: Zero-egress test log from enclave simulator | V401: Zero outbound connections observed during full sequencing cycle | W401: Enclave | X401: MOD-015 | Y401: Not started
...

Sheet Sprint Calendar
A1: Sprint Calendar
A2: Fill one row per sprint. TargetSprint on the Master Checklist must match a Sprint ID here. Without this sheet no item can be given a date.
A4: Sprint ID | B4: Start date | C4: End date | D4: Working days | E4: Stage | F4: Sprint goal | G4: Scope freeze date | H4: Demo date | I4: Notes
A5: PROVISIONAL: S01 | D5: 10 | E5: 0 | F5: PROVISIONAL: Freeze event envelope + competency schema contracts

Sheet Capacity Plan
A1: Capacity Plan
A2: One row per person per sprint. Allocated days pulls from EstDays where Assignee and TargetSprint match. This is the sheet that turns the checklist into a plan.
A4: Person | B4: Role | C4: Squad | D4: Test team | E4: Cost centre | F4: Sprint ID | G4: Available days | H4: Allocated days (from EstDays) | I4: Over-allocated? | J4: Notes
A5: PROVISIONAL: <name> | B5: PROVISIONAL: Backend Engineer | C5: SQ1 Platform Core | D5: — | F5: PROVISIONAL: S01 | G5: 8 | H5: =SUMIFS('Master Checklist'!$M:$M,'Master Checklist'!$L:$L,$A5,'Master Checklist'!$N:$N,$F5) -> 0 | I5: =IF(H5>G5,"YES","")

Sheet Stage Gates
A1: Stage Gates
A2: A stage closes on evidence, not opinion. Gate status is computed; entry/exit criteria and the gate owner are yours to complete.
A4: Stage | B4: Scope | C4: Gate owner | D4: Target date | E4: Items | F4: Done | G4: P0 open | H4: Gate status | I4: Entry criteria | J4: Exit criteria evidence
A5: Stage 0 | B5: Stage 0 — Contracts, schemas & decisions | E5: =COUNTIF('Master Checklist'!$O:$O,0) -> 292 | F5: =COUNTIFS('Master Checklist'!$O:$O,0,'Master Checklist'!$Y:$Y,"Done") -> 0 | G5: =COUNTIFS('Master Checklist'!$O:$O,0,'Master Checklist'!$E:$E,"P0",'Master Checklist'!$Y:$Y,"<>Done") -> 25 | H5: =IF(AND(E5>0,F5=E5),"PASS","OPEN") -> OPEN
A6: Stage 1 | B6: Stage 1 — Slice A validation | E6: =COUNTIF('Master Checklist'!$O:$O,1) -> 498 | F6: =COUNTIFS('Master Checklist'!$O:$O,1,'Master Checklist'!$Y:$Y,"Done") -> 0 | G6: =COUNTIFS('Master Checklist'!$O:$O,1,'Master Checklist'!$E:$E,"P0",'Master Checklist'!$Y:$Y,"<>Done") -> 13 | H6: =IF(AND(E6>0,F6=E6),"PASS","OPEN") -> OPEN
A7: Stage 2 | B7: Stage 2 — Content & competency | E7: =COUNTIF('Master Checklist'!$O:$O,2) -> 496 | F7: =COUNTIFS('Master Checklist'!$O:$O,2,'Master Checklist'!$Y:$Y,"Done") -> 0 | G7: =COUNTIFS('Master Checklist'!$O:$O,2,'Master Checklist'!$E:$E,"P0",'Master Checklist'!$Y:$Y,"<>Done") -> 6 | H7: =IF(AND(E7>0,F7=E7),"PASS","OPEN") -> OPEN
A8: Stage 3 | B8: Stage 3 — AI & field slices | E8: =COUNTIF('Master Checklist'!$O:$O,3) -> 513 | F8: =COUNTIFS('Master Checklist'!$O:$O,3,'Master Checklist'!$Y:$Y,"Done") -> 0 | G8: =COUNTIFS('Master Checklist'!$O:$O,3,'Master Checklist'!$E:$E,"P0",'Master Checklist'!$Y:$Y,"<>Done") -> 6 | H8: =IF(AND(E8>0,F8=E8),"PASS","OPEN") -> OPEN
A9: Stage 4 | B9: Stage 4 — Controlled pilot | E9: =COUNTIF('Master Checklist'!$O:$O,4) -> 212 | F9: =COUNTIFS('Master Checklist'!$O:$O,4,'Master Checklist'!$Y:$Y,"Done") -> 0 | G9: =COUNTIFS('Master Checklist'!$O:$O,4,'Master Checklist'!$E:$E,"P0",'Master Checklist'!$Y:$Y,"<>Done") -> 0 | H9: =IF(AND(E9>0,F9=E9),"PASS","OPEN") -> OPEN
A10: Stage 5 | B10: Stage 5 — Production & scale | E10: =COUNTIF('Master Checklist'!$O:$O,5) -> 109 | F10: =COUNTIFS('Master Checklist'!$O:$O,5,'Master Checklist'!$Y:$Y,"Done") -> 0 | G10: =COUNTIFS('Master Checklist'!$O:$O,5,'Master Checklist'!$E:$E,"P0",'Master Checklist'!$Y:$Y,"<>Done") -> 0 | H10: =IF(AND(E10>0,F10=E10),"PASS","OPEN") -> OPEN

Sheet Defect Log
A1: Defect Log
A2: Every failed test lands here. Fix item ID links the rework back to the Master Checklist so a defect cannot be closed without work being done.
A4: Defect ID | B4: Raised date | C4: Found in item ID | D4: Product | E4: Environment | F4: Test team | G4: Severity (S1-S4) | H4: Summary | I4: Status | J4: Fix item ID | K4: Retest result | L4: Closed date | M4: Owner
A5: PROVISIONAL: DEF-001 | C5: PROVISIONAL: TST-07.1.04 | D5: PROVISIONAL: D12 | E5: PROVISIONAL: Staging | F5: QA-A11Y | G5: S2 | H5: PROVISIONAL: eBook page-turn control unreachable by keyboard | I5: Open

Sheet Environment Register
A1: Environment Register
A2: An item whose environment does not exist is unschedulable. Assign an owner and a readiness date to every row before planning the stage that needs it.
A4: Environment | B4: Purpose | C4: Deployment class served | D4: Owner | E4: Readiness date | F4: Status | G4: Cost basis (INR) | H4: Dependent items | I4: Blocking? | J4: Notes
A5: Enclave simulator | B5: Zero-egress build/test of every Enclave-class item | C5: Enclave | F5: Not funded | H5: =COUNTIF('Master Checklist'!$W:$W,"Enclave") -> 102 | I5: YES | J5: PROVISIONAL: 96+ items cannot be scheduled until this exists
A6: LMS certification | B6: Moodle / Canvas / Open edX conformance runs | C6: All | F6: Not started
A7: Lab edge (reference site) | B7: Edge server + device fleet for D20 | C7: On-prem | F7: Not started
