Workbook

Sheet Summary
A1: EdVidura Builder Clarification Bank — the questions the team needs answered to build
A2: 2,703 clarifications · 41 products + cross-cutting concerns · 17 roles (incl. UI/UX Designer) · 4 levels · 12 lifecycle stages
A3: Written in the builder's voice: every row asks outward for a decision, names the work it blocks, and carries a proposed default so silence does not stop the sprint.
A4: YELLOW columns are yours: AnsweredBy, AnswerDate, DecisionRecord. Change Status as answers arrive.
A6: Headline
A7: Total clarifications | B7: 2703
A8: Blockers — work cannot start | B8: 1132
A9: Hard blockers — no default is possible | B9: 163
A10: Questions nobody currently owns | B10: 139
A11: Needed before sprint 0 | B11: 246
A12: Needed before first code | B12: 839
A13: UI/UX clarifications | B13: 383
A14: Second-wave / seam questions | B14: 1084
A17: By role (live)
A18: Code | B18: Role | C18: Total | D18: L1 | E18: L2 | F18: L3 | G18: L4 | H18: Blockers | I18: Before sprint 0 | J18: Answered
A19: FE | B19: Front-End Developer | C19: =COUNTIF('Clarification Bank'!$D:$D,$A19) -> 156 | D19: =COUNTIFS('Clarification Bank'!$D:$D,$A19,'Clarification Bank'!$F:$F,"L1 Junior") -> 33 | E19: =COUNTIFS('Clarification Bank'!$D:$D,$A19,'Clarification Bank'!$F:$F,"L2 Mid") -> 81 | F19: =COUNTIFS('Clarification Bank'!$D:$D,$A19,'Clarification Bank'!$F:$F,"L3 Senior") -> 21 | G19: =COUNTIFS('Clarification Bank'!$D:$D,$A19,'Clarification Bank'!$F:$F,"L4 Architect") -> 21 | H19: =COUNTIFS('Clarification Bank'!$D:$D,$A19,'Clarification Bank'!$H:$H,"Blocker") -> 55 | I19: =COUNTIFS('Clarification Bank'!$D:$D,$A19,'Clarification Bank'!$I:$I,"Before sprint 0") -> 6 | J19: =COUNTIFS('Clarification Bank'!$D:$D,$A19,'Clarification Bank'!$S:$S,"Answered") -> 0
A20: BE | B20: Back-End Developer | C20: =COUNTIF('Clarification Bank'!$D:$D,$A20) -> 342 | D20: =COUNTIFS('Clarification Bank'!$D:$D,$A20,'Clarification Bank'!$F:$F,"L1 Junior") -> 33 | E20: =COUNTIFS('Clarification Bank'!$D:$D,$A20,'Clarification Bank'!$F:$F,"L2 Mid") -> 197 | F20: =COUNTIFS('Clarification Bank'!$D:$D,$A20,'Clarification Bank'!$F:$F,"L3 Senior") -> 79 | G20: =COUNTIFS('Clarification Bank'!$D:$D,$A20,'Clarification Bank'!$F:$F,"L4 Architect") -> 33 | H20: =COUNTIFS('Clarification Bank'!$D:$D,$A20,'Clarification Bank'!$H:$H,"Blocker") -> 179 | I20: =COUNTIFS('Clarification Bank'!$D:$D,$A20,'Clarification Bank'!$I:$I,"Before sprint 0") -> 16 | J20: =COUNTIFS('Clarification Bank'!$D:$D,$A20,'Clarification Bank'!$S:$S,"Answered") -> 0
A21: DE | B21: Data Engineer | C21: =COUNTIF('Clarification Bank'!$D:$D,$A21) -> 164 | D21: =COUNTIFS('Clarification Bank'!$D:$D,$A21,'Clarification Bank'!$F:$F,"L1 Junior") -> 21 | E21: =COUNTIFS('Clarification Bank'!$D:$D,$A21,'Clarification Bank'!$F:$F,"L2 Mid") -> 74 | F21: =COUNTIFS('Clarification Bank'!$D:$D,$A21,'Clarification Bank'!$F:$F,"L3 Senior") -> 48 | G21: =COUNTIFS('Clarification Bank'!$D:$D,$A21,'Clarification Bank'!$F:$F,"L4 Architect") -> 21 | H21: =COUNTIFS('Clarification Bank'!$D:$D,$A21,'Clarification Bank'!$H:$H,"Blocker") -> 93 | I21: =COUNTIFS('Clarification Bank'!$D:$D,$A21,'Clarification Bank'!$I:$I,"Before sprint 0") -> 7 | J21: =COUNTIFS('Clarification Bank'!$D:$D,$A21,'Clarification Bank'!$S:$S,"Answered") -> 0
A22: BI | B22: BI / Analytics Developer (Metabase) | C22: =COUNTIF('Clarification Bank'!$D:$D,$A22) -> 92 | D22: =COUNTIFS('Clarification Bank'!$D:$D,$A22,'Clarification Bank'!$F:$F,"L1 Junior") -> 21 | E22: =COUNTIFS('Clarification Bank'!$D:$D,$A22,'Clarification Bank'!$F:$F,"L2 Mid") -> 29 | F22: =COUNTIFS('Clarification Bank'!$D:$D,$A22,'Clarification Bank'!$F:$F,"L3 Senior") -> 21 | G22: =COUNTIFS('Clarification Bank'!$D:$D,$A22,'Clarification Bank'!$F:$F,"L4 Architect") -> 21 | H22: =COUNTIFS('Clarification Bank'!$D:$D,$A22,'Clarification Bank'!$H:$H,"Blocker") -> 22 | I22: =COUNTIFS('Clarification Bank'!$D:$D,$A22,'Clarification Bank'!$I:$I,"Before sprint 0") -> 6 | J22: =COUNTIFS('Clarification Bank'!$D:$D,$A22,'Clarification Bank'!$S:$S,"Answered") -> 0
A23: DA | B23: Data Analyst | C23: =COUNTIF('Clarification Bank'!$D:$D,$A23) -> 100 | D23: =COUNTIFS('Clarification Bank'!$D:$D,$A23,'Clarification Bank'!$F:$F,"L1 Junior") -> 21 | E23: =COUNTIFS('Clarification Bank'!$D:$D,$A23,'Clarification Bank'!$F:$F,"L2 Mid") -> 32 | F23: =COUNTIFS('Clarification Bank'!$D:$D,$A23,'Clarification Bank'!$F:$F,"L3 Senior") -> 26 | G23: =COUNTIFS('Clarification Bank'!$D:$D,$A23,'Clarification Bank'!$F:$F,"L4 Architect") -> 21 | H23: =COUNTIFS('Clarification Bank'!$D:$D,$A23,'Clarification Bank'!$H:$H,"Blocker") -> 35 | I23: =COUNTIFS('Clarification Bank'!$D:$D,$A23,'Clarification Bank'!$I:$I,"Before sprint 0") -> 9 | J23: =COUNTIFS('Clarification Bank'!$D:$D,$A23,'Clarification Bank'!$S:$S,"Answered") -> 0
A24: AI | B24: AI/ML Engineer | C24: =COUNTIF('Clarification Bank'!$D:$D,$A24) -> 146 | D24: =COUNTIFS('Clarification Bank'!$D:$D,$A24,'Clarification Bank'!$F:$F,"L1 Junior") -> 21 | E24: =COUNTIFS('Clarification Bank'!$D:$D,$A24,'Clarification Bank'!$F:$F,"L2 Mid") -> 44 | F24: =COUNTIFS('Clarification Bank'!$D:$D,$A24,'Clarification Bank'!$F:$F,"L3 Senior") -> 55 | G24: =COUNTIFS('Clarification Bank'!$D:$D,$A24,'Clarification Bank'!$F:$F,"L4 Architect") -> 26 | H24: =COUNTIFS('Clarification Bank'!$D:$D,$A24,'Clarification Bank'!$H:$H,"Blocker") -> 95 | I24: =COUNTIFS('Clarification Bank'!$D:$D,$A24,'Clarification Bank'!$I:$I,"Before sprint 0") -> 17 | J24: =COUNTIFS('Clarification Bank'!$D:$D,$A24,'Clarification Bank'!$S:$S,"Answered") -> 0
A25: AIG | B25: AI Generalist | C25: =COUNTIF('Clarification Bank'!$D:$D,$A25) -> 84 | D25: =COUNTIFS('Clarification Bank'!$D:$D,$A25,'Clarification Bank'!$F:$F,"L1 Junior") -> 21 | E25: =COUNTIFS('Clarification Bank'!$D:$D,$A25,'Clarification Bank'!$F:$F,"L2 Mid") -> 21 | F25: =COUNTIFS('Clarification Bank'!$D:$D,$A25,'Clarification Bank'!$F:$F,"L3 Senior") -> 21 | G25: =COUNTIFS('Clarification Bank'!$D:$D,$A25,'Clarification Bank'!$F:$F,"L4 Architect") -> 21 | H25: =COUNTIFS('Clarification Bank'!$D:$D,$A25,'Clarification Bank'!$H:$H,"Blocker") -> 38 | I25: =COUNTIFS('Clarification Bank'!$D:$D,$A25,'Clarification Bank'!$I:$I,"Before sprint 0") -> 6 | J25: =COUNTIFS('Clarification Bank'!$D:$D,$A25,'Clarification Bank'!$S:$S,"Answered") -> 0
A26: MXR | B26: Mobile & XR Developer | C26: =COUNTIF('Clarification Bank'!$D:$D,$A26) -> 92 | D26: =COUNTIFS('Clarification Bank'!$D:$D,$A26,'Clarification Bank'!$F:$F,"L1 Junior") -> 21 | E26: =COUNTIFS('Clarification Bank'!$D:$D,$A26,'Clarification Bank'!$F:$F,"L2 Mid") -> 29 | F26: =COUNTIFS('Clarification Bank'!$D:$D,$A26,'Clarification Bank'!$F:$F,"L3 Senior") -> 21 | G26: =COUNTIFS('Clarification Bank'!$D:$D,$A26,'Clarification Bank'!$F:$F,"L4 Architect") -> 21 | H26: =COUNTIFS('Clarification Bank'!$D:$D,$A26,'Clarification Bank'!$H:$H,"Blocker") -> 47 | I26: =COUNTIFS('Clarification Bank'!$D:$D,$A26,'Clarification Bank'!$I:$I,"Before sprint 0") -> 12 | J26: =COUNTIFS('Clarification Bank'!$D:$D,$A26,'Clarification Bank'!$S:$S,"Answered") -> 0
A27: DEVOPS | B27: DevSecOps / Platform Engineer | C27: =COUNTIF('Clarification Bank'!$D:$D,$A27) -> 168 | D27: =COUNTIFS('Clarification Bank'!$D:$D,$A27,'Clarification Bank'!$F:$F,"L1 Junior") -> 21 | E27: =COUNTIFS('Clarification Bank'!$D:$D,$A27,'Clarification Bank'!$F:$F,"L2 Mid") -> 56 | F27: =COUNTIFS('Clarification Bank'!$D:$D,$A27,'Clarification Bank'!$F:$F,"L3 Senior") -> 70 | G27: =COUNTIFS('Clarification Bank'!$D:$D,$A27,'Clarification Bank'!$F:$F,"L4 Architect") -> 21 | H27: =COUNTIFS('Clarification Bank'!$D:$D,$A27,'Clarification Bank'!$H:$H,"Blocker") -> 59 | I27: =COUNTIFS('Clarification Bank'!$D:$D,$A27,'Clarification Bank'!$I:$I,"Before sprint 0") -> 16 | J27: =COUNTIFS('Clarification Bank'!$D:$D,$A27,'Clarification Bank'!$S:$S,"Answered") -> 0
A28: SEC | B28: Security Engineer | C28: =COUNTIF('Clarification Bank'!$D:$D,$A28) -> 172 | D28: =COUNTIFS('Clarification Bank'!$D:$D,$A28,'Clarification Bank'!$F:$F,"L1 Junior") -> 21 | E28: =COUNTIFS('Clarification Bank'!$D:$D,$A28,'Clarification Bank'!$F:$F,"L2 Mid") -> 44 | F28: =COUNTIFS('Clarification Bank'!$D:$D,$A28,'Clarification Bank'!$F:$F,"L3 Senior") -> 83 | G28: =COUNTIFS('Clarification Bank'!$D:$D,$A28,'Clarification Bank'!$F:$F,"L4 Architect") -> 24 | H28: =COUNTIFS('Clarification Bank'!$D:$D,$A28,'Clarification Bank'!$H:$H,"Blocker") -> 102 | I28: =COUNTIFS('Clarification Bank'!$D:$D,$A28,'Clarification Bank'!$I:$I,"Before sprint 0") -> 8 | J28: =COUNTIFS('Clarification Bank'!$D:$D,$A28,'Clarification Bank'!$S:$S,"Answered") -> 0
A29: QA | B29: QA / Test Engineer | C29: =COUNTIF('Clarification Bank'!$D:$D,$A29) -> 134 | D29: =COUNTIFS('Clarification Bank'!$D:$D,$A29,'Clarification Bank'!$F:$F,"L1 Junior") -> 21 | E29: =COUNTIFS('Clarification Bank'!$D:$D,$A29,'Clarification Bank'!$F:$F,"L2 Mid") -> 65 | F29: =COUNTIFS('Clarification Bank'!$D:$D,$A29,'Clarification Bank'!$F:$F,"L3 Senior") -> 27 | G29: =COUNTIFS('Clarification Bank'!$D:$D,$A29,'Clarification Bank'!$F:$F,"L4 Architect") -> 21 | H29: =COUNTIFS('Clarification Bank'!$D:$D,$A29,'Clarification Bank'!$H:$H,"Blocker") -> 32 | I29: =COUNTIFS('Clarification Bank'!$D:$D,$A29,'Clarification Bank'!$I:$I,"Before sprint 0") -> 2 | J29: =COUNTIFS('Clarification Bank'!$D:$D,$A29,'Clarification Bank'!$S:$S,"Answered") -> 0
A30: SDET | B30: Test Architect / SDET | C30: =COUNTIF('Clarification Bank'!$D:$D,$A30) -> 124 | D30: =COUNTIFS('Clarification Bank'!$D:$D,$A30,'Clarification Bank'!$F:$F,"L1 Junior") -> 21 | E30: =COUNTIFS('Clarification Bank'!$D:$D,$A30,'Clarification Bank'!$F:$F,"L2 Mid") -> 30 | F30: =COUNTIFS('Clarification Bank'!$D:$D,$A30,'Clarification Bank'!$F:$F,"L3 Senior") -> 52 | G30: =COUNTIFS('Clarification Bank'!$D:$D,$A30,'Clarification Bank'!$F:$F,"L4 Architect") -> 21 | H30: =COUNTIFS('Clarification Bank'!$D:$D,$A30,'Clarification Bank'!$H:$H,"Blocker") -> 40 | I30: =COUNTIFS('Clarification Bank'!$D:$D,$A30,'Clarification Bank'!$I:$I,"Before sprint 0") -> 2 | J30: =COUNTIFS('Clarification Bank'!$D:$D,$A30,'Clarification Bank'!$S:$S,"Answered") -> 0
... A35: UXD | B35: UI/UX Designer | C35: =COUNTIF('Clarification Bank'!$D:$D,$A35) -> 315 | D35: =COUNTIFS('Clarification Bank'!$D:$D,$A35,'Clarification Bank'!$F:$F,"L1 Junior") -> 31 | E35: =COUNTIFS('Clarification Bank'!$D:$D,$A35,'Clarification Bank'!$F:$F,"L2 Mid") -> 172 | F35: =COUNTIFS('Clarification Bank'!$D:$D,$A35,'Clarification Bank'!$F:$F,"L3 Senior") -> 91 | G35: =COUNTIFS('Clarification Bank'!$D:$D,$A35,'Clarification Bank'!$F:$F,"L4 Architect") -> 21 | H35: =COUNTIFS('Clarification Bank'!$D:$D,$A35,'Clarification Bank'!$H:$H,"Blocker") -> 102 | I35: =COUNTIFS('Clarification Bank'!$D:$D,$A35,'Clarification Bank'!$I:$I,"Before sprint 0") -> 8 | J35: =COUNTIFS('Clarification Bank'!$D:$D,$A35,'Clarification Bank'!$S:$S,"Answered") -> 0
B36: TOTAL | C36: =SUM(C19:C35) -> 2703 | D36: =SUM(D19:D35) -> 391 | E36: =SUM(E19:E35) -> 1092 | F36: =SUM(F19:F35) -> 810 | G36: =SUM(G19:G35) -> 410 | H36: =SUM(H19:H35) -> 1132 | I36: =SUM(I19:I35) -> 246 | J36: =SUM(J19:J35) -> 0
A38: By answerer — this is your meeting list
A39: Addressed to | B39: Questions | C39: Blockers | D39: Hard blockers | E39: Before sprint 0
A40: Solution Architect | B40: 598 | C40: 276 | D40: 2 | E40: 41
A41: Product Owner | B41: 564 | C41: 162 | D41: 4 | E41: 48
A42: Programme Manager | B42: 422 | C42: 108 | D42: 10 | E42: 73
A43: Security/Accreditation | B43: 243 | C43: 127 | D43: 7 | E43: 9
A44: Legal & Compliance | B44: 195 | C44: 105 | D44: 9 | E44: 13
A45: Client SME | B45: 151 | C45: 84 | D45: 29 | E45: 26
A46: Instructional Designer | B46: 150 | C46: 57 | D46: 0 | E46: 3
A47: Data Owner | B47: 149 | C47: 63 | D47: 1 | E47: 0
A48: NOBODY OWNS THIS | B48: 139 | C48: 120 | D48: 101 | E48: 30
...

Sheet Critical Answer Path
A1: Critical Answer Path
A2: The hard blockers, in the order they are needed. These cannot be defaulted — you cannot invent a customer's LMS, a competency framework, a GPU budget or an accrediting authority. Answer these and the largest amount of blocked work moves. Ordered by when it is needed, then by product.
A4: # | B4: Needed by | C4: ProductID | D4: Product | E4: Question — no default is possible | F4: Who must answer | G4: What it blocks | H4: Answer must arrive as | I4: CQID | J4: Answered? | K4: Date
A5: 1 | B5: Before sprint 0 | C5: D01 | D5: AI SME Chatbot — Learner-Facing | E5: What GPU hardware will actually be in the enclave appliance - count, model and VRAM - because I cannot size batch, context window or resident model count without it? | F5: NOBODY OWNS THIS | G5: I cannot size anything: context length, concurrency, resident models, or whether chat and grading co-reside | H5: signed document | I5: CQC0012
A6: 2 | B6: Before sprint 0 | C6: D02 | D6: AI Assessment Tools & Test Banks + Auto Grader | E6: Should grading run on a larger model than the chatbot on the same appliance, or must both share one model - because this decision drives VRAM and therefore procurement? | F6: NOBODY OWNS THIS | G6: I cannot write the sizing memo, and procurement with a two-quarter lead time cannot start | H6: decision record | I6: CQC0045
A7: 3 | B7: Before sprint 0 | C7: D03 | D7: Security Accreditation & Authorisation to Operate — Initiation | E7: Which organisation actually issues the Authorisation to Operate for EdVidura at customer one - name the accrediting body and the role title of the officer who signs it - because until I have that name I cannot tell you which control catalogue, which templates or which submission route the package must use? | F7: NOBODY OWNS THIS | G7: Every artefact in D03 - I cannot start the System Security Plan, the risk assessment or the evidence index without knowing whose format they must be in | H7: named person | I7: CQF0001
A8: 4 | B8: Before sprint 0 | C8: D03 | D8: Security Accreditation & Authorisation to Operate — Initiation | E8: Which control baseline are we assessed against - ISO/IEC 27001:2022 Annex A, NIST SP 800-53 Rev 5 at Moderate, CERT-In plus MeitY guidance, or a customer-specific catalogue - and is that choice ours or theirs? | F8: NOBODY OWNS THIS | G8: The control-to-evidence mapping spreadsheet, the SSP structure and the scope of the gap assessment | H8: signed document | I8: CQF0002
A9: 5 | B9: Before sprint 0 | C9: D04 | D9: Pedagogy Design Review Protocol | E9: Who is the assessor - a named instructional designer, a panel, or the customer training authority - because a protocol with no named reviewer is a document nobody executes? | F9: NOBODY OWNS THIS | G9: The whole operating model of the protocol and the queue design behind it | H9: named person | I9: CQD0171
A10: 6 | B10: Before sprint 0 | C10: D05 | D10: TLA CMM Level 2 — Microservices | E10: Who is the assessor - an EdVidura independent reviewer, a customer body, or an external accreditation authority - and have they been engaged or is that name still blank? | F10: NOBODY OWNS THIS | G10: the assessment date, the evidence deadline and the whole L2 critical path | H10: named person | I10: CQA0111
A11: 7 | B11: Before sprint 0 | C11: D05 | D11: TLA CMM Level 2 — Microservices | E11: Which published version of the TLA Capability Maturity Model are we being assessed against, and can somebody send me the document - because I cannot write conformance criteria against a model I have not read. | F11: Client SME | G11: every criterion, every evidence item and the scoring rubric | H11: link to existing spec | I11: CQA0110
A12: 8 | B12: Before sprint 0 | C12: D07 | D12: TLA Course Catalogue (ECC) | E12: How many courses are in customer one catalogue today and how many organisations own them - because ten owners and two hundred courses is a very different product from two hundred owners and twenty thousand? | F12: Client SME | G12: the search design, the governance model and the onboarding plan | H12: number with units | I12: CQB0055
A13: 9 | B13: Before sprint 0 | C13: D08 | D13: TLA Competency-Registry | E13: Who at the customer is the competency authority - the person who can say this competency exists and this is what it means - because every rule in this product needs their name against it? | F13: Client SME | G13: the approval workflows, the deprecation process and the adjudication path | H13: named person | I13: CQB0094
A14: 10 | B14: Before sprint 0 | C14: D08 | D14: TLA Competency-Registry | E14: Which competency framework are we implementing - a customer framework, an existing published one, or one we author - because I cannot design the registry schema until a framework is named and licensed? | F14: Client SME | G14: the schema, every API, the catalogue integration, the assessment tool and the whole product estimate | H14: signed document | I14: CQB0072
A15: 11 | B15: Before sprint 0 | C15: D09 | D15: TLA CMM Level 3 | E15: Who is the assessor for Level 3 - an internal panel, the client authority, or an accredited external body - and are they booked? | F15: Client SME | G15: the assessment date, the evidence deadline and the whole plan backward from it | H15: named person | I15: CQB0181
A16: 12 | B16: Before sprint 0 | C16: D09 | D16: TLA CMM Level 3 | E16: Which published capability maturity model are we being assessed against for TLA Level 3 - is there a named document with numbered practices, and can I have the current version of it? | F16: Client SME | G16: the entire attainment plan, the evidence schedule and the estimate | H16: signed document | I16: CQB0178
... A64: 60 | B64: Before sprint 0 | C64: XCUT | D64: Cross-cutting concern / Whole Product | E64: Give me the actual environment list - dev, integration, staging, enclave-representative, demo, production - with a named owner for each, because squads are currently creating their own and calling them staging? | F64: NOBODY OWNS THIS | G64: Every deployment target decision and every conversation that starts with which staging do you mean | H64: named person | I64: CQF0198

Sheet Escalation — nobody owns this
A1: Escalation — nobody owns this
A2: Decisions with no current owner. These are not meetings — they are a governance finding. Each needs a name attached before it can even be scheduled. This sheet is the shortest route to the programme's real risk.
A4: ProductID | B4: Product | C4: Blocking | D4: Hard? | E4: Needed by | F4: Asked by | G4: Question | H4: Proposed default | I4: Cost if wrong | J4: CQID | K4: Owner assigned | L4: Date
A5: D01 | B5: AI SME Chatbot — Learner-Facing | C5: Blocker | D5: HARD | E5: Before sprint 0 | F5: AI | G5: What GPU hardware will actually be in the enclave appliance - count, model and VRAM - because I cannot size batch, context window or resident model count without it? | H5: HARD BLOCKER - no default possible | I5: every latency, concurrency and quality number we publish is unfounded, and procurement lead time is quoted at two quarters | J5: CQC0012
A6: D02 | B6: AI Assessment Tools & Test Banks + Auto Grader | C6: Blocker | D6: HARD | E6: Before sprint 0 | F6: AI | G6: Should grading run on a larger model than the chatbot on the same appliance, or must both share one model - because this decision drives VRAM and therefore procurement? | H6: HARD BLOCKER - no default possible | I6: one model may be too weak for grading and two may not fit; either way the appliance is bought wrong and cannot be changed for two quarters | J6: CQC0045
A7: D03 | B7: Security Accreditation & Authorisation to Operate — Initiation | C7: Blocker | D7: HARD | E7: Before sprint 0 | F7: SEC | G7: Which organisation actually issues the Authorisation to Operate for EdVidura at customer one - name the accrediting body and the role title of the officer who signs it - because until I have that name I cannot tell you which control catalogue, which templates or which submission route the package must use? | H7: HARD BLOCKER - no default possible | I7: Writing the package to the wrong authority means the whole submission is rejected on format alone and rebuilt from scratch - six to ten weeks and a missed go-live | J7: CQF0001
A8: D03 | B8: Security Accreditation & Authorisation to Operate — Initiation | C8: Blocker | D8: HARD | E8: Before sprint 0 | F8: SEC | G8: Which control baseline are we assessed against - ISO/IEC 27001:2022 Annex A, NIST SP 800-53 Rev 5 at Moderate, CERT-In plus MeitY guidance, or a customer-specific catalogue - and is that choice ours or theirs? | H8: HARD BLOCKER - no default possible | I8: A baseline swap after evidence collection starts is a full re-index of every artefact plus new controls we never implemented - a quarter of engineering effort in the worst case | J8: CQF0002
A9: D04 | B9: Pedagogy Design Review Protocol | C9: Blocker | D9: HARD | E9: Before sprint 0 | F9: ID | G9: Who is the assessor - a named instructional designer, a panel, or the customer training authority - because a protocol with no named reviewer is a document nobody executes? | H9: HARD BLOCKER - no default possible | I9: A protocol with no staffed reviewer role is written, signed and never executed; content ships unreviewed and the gate exists only on paper | J9: CQD0171
A10: D05 | B10: TLA CMM Level 2 — Microservices | C10: Blocker | D10: HARD | E10: Before sprint 0 | F10: PM | G10: Who is the assessor - an EdVidura independent reviewer, a customer body, or an external accreditation authority - and have they been engaged or is that name still blank? | H10: HARD BLOCKER - no default possible | I10: An assessment date that never gets booked, so a contractual maturity claim is made with nobody having assessed it. | J10: CQA0111
A11: D09 | B11: TLA CMM Level 3 | C11: Blocker | D11: HARD | E11: Before sprint 0 | F11: PM | G11: Which external organisation are we demonstrating interoperability with for Level 3 - because the practices require a real external partner and none has been named? | H11: HARD BLOCKER - no default possible | I11: The attainment cannot be achieved at all - no substitute demonstration will satisfy an assessor who asks who you interoperated with | J11: CQB0180
A12: D14 | B12: Personalized Learning Engine — Core | C12: Blocker | D12: HARD | E12: Before sprint 0 | F12: DE | G12: Where do content metadata and the competency framework come from - the ECC catalogue and M19 registry - and do those schemas exist today in any version I can build against? | H12: HARD BLOCKER - no default possible | I12: building sequencing before the content and competency schemas exist is the classic adaptive-learning-without-an-ontology failure | J12: CQC0114
A13: D22 | B13: AI/ML Procedural Walkthrough Engine | C13: Blocker | D13: HARD | E13: Before sprint 0 | F13: MXR | G13: What is the capture stack - headset hand tracking, external cameras, instrumented tools, or a mix - because the whole engine design follows from it? | H13: HARD BLOCKER - no default possible | I13: every downstream decision - confidence metadata, occlusion handling, data volume, privacy posture - depends on hardware nobody has selected | J13: CQC0133
A14: D23 | B14: Difference Training Application | C14: Blocker | D14: HARD | E14: Before sprint 0 | F14: DE | G14: Which system of record tells me that a named learner is assigned to a named piece of equipment at a named variant - I cannot find one, and without it there is no such thing as a difference for a person? | H14: HARD BLOCKER - no default possible | I14: Every gap is computed against an invented assignment model; when the real source appears with different granularity - by role, by unit, by serial number - the model, the feed and the screens are all rebuilt | J14: CQD0138
A15: D25 | B15: Accelerate Upgrade Readiness Measurement Plan | C15: Blocker | D15: HARD | E15: Before sprint 0 | F15: DA | G15: Where does the pre-rollout baseline come from - existing training records in a client system, paper registers at the site, or an SME recollection - and does that source contain per-trainee dates or only cohort totals? | H15: HARD BLOCKER - no default possible | I15: There is no recovery - once rollout starts at a site, the pre-rollout state of that site cannot be reconstructed and the acceleration claim for it is dead | J15: CQF0038
A16: D25 | B16: Accelerate Upgrade Readiness Measurement Plan | C16: Blocker | D16: HARD | E16: Before sprint 0 | F16: DA | G16: Who accepts the measurement definitions as fair before we start collecting - a client SME, an independent evaluator, or nobody - because a definition accepted only by us is worthless the moment the client disputes the result? | H16: HARD BLOCKER - no default possible | I16: An unaccepted definition means the client rejects the result at the end of a twelve-month measurement period and there is no second baseline to redo it against | J16: CQF0037
... A38: D02 | B38: AI Assessment Tools & Test Banks + Auto Grader | C38: Blocker | D38: HARD | E38: Before first code | F38: AI | G38: What is the grading evaluation dataset - scored answers with human gold grades - and how many items per language do I need before any threshold can be argued? | H38: HARD BLOCKER - no default possible | I38: without it the 100 percent review default is permanent by default rather than by decision, and no gate can ever be passed | J38: CQC0043
A39: D18 | B39: Analytics Dashboard Suite (incl. TLA) — All Roles | C39: Blocker | E39: Before first code | F39: SEC | G39: Who owns the row-level security policies on the analytics marts - my squad, the data platform squad, or the security team - because right now three groups each assume another one writes them and none exist? | H39: The data platform squad authors the policies, security reviews and signs them, and no policy change merges without both approvals recorded in the mart repository | I39: Unowned policies drift, a tenant sees another tenant's learners, and we take an accreditation finding that stops the release rather than a bug we can patch | J39: CQE0002
A40: D18 | B40: Analytics Dashboard Suite (incl. TLA) — All Roles | C40: Blocker | E40: Before first code | F40: UXD | G40: Do the five surfaces in this group - dashboards, XR store, microlearning app, MOE AR capture and the lab console - share one component library, and who owns and versions it? | H40: One shared token set - colour, type scale, spacing, iconography - owned by the design squad, with separate component implementations per platform because web, Unity and native mobile cannot share code | I40: Five surfaces that look like five products from different vendors, then a costly visual harmonisation pass late, plus duplicated accessibility work | J40: CQE0019
A41: D22 | B41: AI/ML Procedural Walkthrough Engine | C41: Blocker | D41: HARD | E41: Before first code | F41: MXR | G41: What confidence value is too low to score - below what number does a step go to human review instead of being marked failed? | H41: HARD BLOCKER - no default possible | I41: auto-failing a step on degraded sensor data creates a false finding against a trainee that is very hard to reverse | J41: CQC0135
A42: D23 | B42: Difference Training Application | C42: Blocker | E42: Before first code | F42: DE | G42: Who owns the equipment and variant identifiers - is there a controlled taxonomy of variants I map to, or do I mint my own identifiers and hope everyone agrees? | H42: Mint EdVidura variant identifiers from the applicability metadata carried on manuals, and keep a mapping table that a human can correct | I42: Two products minting different variant identifiers means the manual applicability and the assignment feed never join, and every gap is wrong or missing | J42: CQD0140
A43: D28 | B43: TLA CMM Level 5 — Enterprise Competency Mapping | C43: Blocker | D43: HARD | E43: Before first code | F43: ID | G43: For enterprise competency mapping, who has the authority to declare that a role requires a given competency - the unit, a central authority, or a joint board? | H43: HARD BLOCKER - no default possible | I43: We produce a mapping dataset with no authority behind it, which an assessor will correctly treat as an unsanctioned spreadsheet | J43: CQB0216
A44: E08 | B44: Customer Onboarding, Tenant Provisioning & Data Migration | C44: Blocker | D44: HARD | E44: Before first code | F44: DE | G44: What evidence level must a migrated completion record carry - self-asserted, an extract signed by the source system owner, or full underlying evidence artefacts? | H44: HARD BLOCKER - no default possible | I44: If migrated records are later judged inadmissible, every certificate and competency claim derived from them is withdrawn and the customer relationship goes with it | J44: CQG0040
A45: XCUT | B45: Cross-cutting concern / Whole Product | C45: Blocker | D45: HARD | E45: Before first code | F45: PM | G45: Which licence metering model must the product actually enforce - per learner per month, per seat perpetual with maintenance, per site, or per headset? | H45: HARD BLOCKER - no default possible | I45: Implementing per-seat metering when the commercial model turns out to be per-site means the entitlement service, the licence file and every admin screen are rebuilt after the first contract is signed | J45: CQG0269
A46: XCUT | B46: Cross-cutting concern / Whole Product | C46: Blocker | D46: HARD | E46: Before first code | F46: SDET | G46: Who owns and maintains the register of published interfaces, and is it a document, a repository or a service - because the conformance suite has to be generated from it and it does not exist yet? | H46: HARD BLOCKER - no default possible | I46: Without a register the conformance suite scope is guesswork, deprecation notices go to nobody, and each squad decides unilaterally what it owes the outside world | J46: CQF0240
A47: XCUT | B47: Cross-cutting concern / Whole Product | C47: Blocker | D47: HARD | E47: Before first code | F47: DE | G47: Who owns the event envelope every product publishes into - the fields, the versioning, the correlation identifier - because three squads have each invented their own envelope and they are already incompatible? | H47: HARD BLOCKER - no default possible | I47: Three incompatible envelopes means no cross-product correlation, no shared consumer tooling and a migration touching every producer once someone finally decides | J47: CQF0241
A48: XCUT | B48: Cross-cutting concern / Whole Product | C48: Blocker | D48: HARD | E48: Before first code | F48: AI | G48: Which embedding model do we use, is it enclave-legal by licence, and who approved it? | H48: HARD BLOCKER - no default possible | I48: choosing an embedding model that turns out to be licence-incompatible with the enclave means re-embedding the entire corpus | J48: CQC0202
A49: XCUT | B49: Cross-cutting concern / Whole Product | C49: Blocker | E49: Before first code | F49: SEC | G49: Who writes, reviews and owns the row-level security policies - I need a named owner and a change process, because a policy edited by anyone with database access is not a control? | H49: Policies live as migrations in the mart repository, authored by the data platform squad, requiring a security approver on every pull request, with direct production edits blocked | I49: Unowned and unreviewed policies are the single most likely cause of a cross-tenant leak, and there is no audit trail to prove otherwise afterwards | J49: CQE0194
A50: XCUT | B50: Cross-cutting concern / Whole Product | C50: Blocker | D50: HARD | E50: Before first code | F50: SDET | G50: Who owns the shared synthetic dataset - its content, its volume, its Indic text coverage and its refresh - because every squad has now built a different one and integration tests fail on data shape not defects? | H50: HARD BLOCKER - no default possible | I50: Per-squad datasets mean cross-product tests fail for data reasons weekly, teams stop trusting integration results and the platform gate becomes noise | J50: CQF0210
A51: XCUT | B51: Cross-cutting concern / Whole Product | C51: Blocker | D51: HARD | E51: Before first code | F51: AI | G51: How fast must a tombstoned chunk stop being retrievable - do I check tombstones at query time on every request, or wait for the next re-index? | H51: HARD BLOCKER - no default possible | I51: query-time checking costs latency on every request forever; re-index-only leaves a window in which withdrawn safety content is still answerable | J51: CQC0207
A52: XCUT | B52: Cross-cutting concern / Whole Product | C52: Blocker | D52: HARD | E52: Before first code | F52: DE | G52: Who may add an xAPI verb or activity type to the platform vocabulary, what is the approval process, and what do I do today when I need one that does not exist? | H52: HARD BLOCKER - no default possible | I52: Squads inventing verbs privately means the records store fills with near-duplicate vocabulary and every analytics query has to know all the variants forever | J52: CQF0242
A53: XCUT | B53: Cross-cutting concern / Whole Product | C53: Blocker | E53: Before first code | F53: DA | G53: Who owns a metric definition once it is in the semantic layer - can a squad add a new definition of completion, or must every metric go through one owner? | H53: One metric catalogue with a single named owner; squads propose definitions by pull request and no dashboard may use a metric that is not in the catalogue | I53: Without a single owner, four squads each define active learner differently and the customer sees four different numbers for the same thing | J53: CQE0198
A54: XCUT | B54: Cross-cutting concern / Whole Product | C54: Blocker | D54: HARD | E54: Before first code | F54: AI | G54: Who authors the retrieval evaluation set - the query, the gold chunks, the gold answer - and how many items per language do we need? | H54: HARD BLOCKER - no default possible | I54: the evaluation set is the single artefact that makes every AI quality claim testable, and nobody is funded to write it | J54: CQC0211
A55: D06 | B55: TLA Experience-Index (ELRR) | C55: Blocker | D55: HARD | E55: Before first integration | F55: DA | G55: When two sources report the same completion with different dates and different results, which wins - most recent, most authoritative source, or the record with an assertion attached? | H55: HARD BLOCKER - no default possible | I55: Every conflicting record is resolved by whichever rule an engineer picked, with no authority behind it, and the first disputed record exposes that | J55: CQB0027
A56: D08 | B56: TLA Competency-Registry | C56: Blocker | D56: HARD | E56: Before first integration | F56: BE | G56: If two organisations both assert the same person holds the same competency at different proficiency levels, does my registry store both, keep the higher, or refuse to store the second? | H56: HARD BLOCKER - no default possible | I56: The registry silently picks a winner with no authority behind the choice, and a person capability record differs depending on which system you ask | J56: CQB0104
A57: D15 | B57: Competency Assessment Tool | C57: Blocker | D57: HARD | E57: Before first integration | F57: ID | G57: If an assessment result influences somebody's job assignment, does that raise the psychometric standard we must meet - and who here is qualified to certify that we meet it? | H57: HARD BLOCKER - no default possible | I57: using an instrument built to formative standards for a consequential decision is challengeable by the individual affected, and we have no qualified signatory to defend it | J57: CQU0132
A58: D16 | B58: TLA Profile Management — Initial Deployment | C58: Blocker | D58: HARD | E58: Before first integration | F58: BE | G58: How do I decide that a person in enclave A and a person in enclave B are the same human when the two have separate identity realms and no shared identifier? | H58: HARD BLOCKER - no default possible | I58: Either we never link a person across enclaves and the enterprise view is fiction, or we match on weak attributes and attach one person records to another - which is the worst failure this platform can have | J58: CQB0112
A59: D17 | B59: Cross-Organisation / Cross-Command Data Pipeline | C59: Blocker | D59: HARD | E59: Before first integration | F59: DA | G59: When a federated record and a local record describe the same completion, does the local one always win, or does the issuing organisation always win regardless of who is reading? | H59: HARD BLOCKER - no default possible | I59: The same person appears differently qualified depending on which organisation system you look at, with no rule anyone can point to | J59: CQB0167
A60: D17 | B60: Cross-Organisation / Cross-Command Data Pipeline | C60: Blocker | D60: HARD | E60: Before first integration | F60: BE | G60: When two organisations send conflicting records about the same person and the same event, who adjudicates - is there a precedence rule, an authority ranking, or a human queue with a named owner? | H60: HARD BLOCKER - no default possible | I60: The pipeline picks a winner by an engineering rule with no authority behind it, and the first time a person qualification is disputed we cannot say who decided or why | J60: CQB0148
A61: D29 | B61: Full Multiverse Platform Integration & Acceptance | C61: Blocker | D61: HARD | E61: Before first integration | F61: PM | G61: What is the pass criterion - zero critical and zero major defects, or a defect budget such as no criticals and up to five majors with agreed workarounds - and who set that number? | H61: HARD BLOCKER - no default possible | I61: Assuming a defect budget when the client expects zero defects means we walk into the event with five open majors and are rejected on the first one | J61: CQF0103
A62: D29 | B62: Full Multiverse Platform Integration & Acceptance | C62: Blocker | D62: HARD | E62: Before first integration | F62: SDET | G62: Do we demonstrate performance and load at acceptance, and against which numbers - because the concurrency, latency and volume targets the tests would execute against have never been published anywhere I can find? | H62: HARD BLOCKER - no default possible | I62: Demonstrating performance against numbers we invented means the client can reject the result by naming different numbers, and we have no basis to argue | J62: CQF0118
...

Sheet Product Kickoff Packs
A1: Product Kickoff Packs
A2: Filter to one ProductID and this is the squad's kickoff agenda: every question that product needs answered, grouped by lifecycle stage (Understand → Scope → Interfaces → Data → Rules → UI/UX → Failure → Non-functionals → BuildEnv → Test&Acceptance → Deploy&Operate → Handover), blockers first within each stage.
A4: ProductID | B4: Product | C4: Lifecycle stage | D4: # | E4: Blocking | F4: Needed by | G4: Role | H4: Level | I4: Question | J4: Proposed default | K4: Ask | L4: CQID | M4: Answer / decision
A5: D01 | B5: AI SME Chatbot — Learner-Facing | C5: Understand | D5: 1 | E5: Blocker | F5: Before first code | G5: AI | H5: L1 Junior | I5: Which document set is the learner chatbot allowed to answer from on day one - only manuals approved in the M25 lineage service, or also DCT-authored lessons and course pages? | J5: approved technical manuals only; DCT lessons excluded until a separate corpus decision is recorded | K5: Product Owner | L5: CQC0001
A6: D01 | B6: AI SME Chatbot — Learner-Facing | C6: Understand | D6: 2 | E6: Blocker | F6: Before first code | G6: AIG | H6: L1 Junior | I6: Who is the named owner of the guardrail policy - the person I go to when a case is not covered - because right now the answer to a novel case is whatever the engineer on the ticket decides? | J6: A named guardrail policy owner in the product team, with a decision log where each novel case and its ruling is recorded and becomes an evaluation case | K6: Programme Manager | L6: CQT0146
A7: D01 | B7: AI SME Chatbot — Learner-Facing | C7: Understand | D7: 3 | E7: Blocker | F7: Before first code | G7: AIG | H7: L4 Architect | I7: Do we run one assistant serving learners and authors with role-based prompts and corpus filters, or three separate deployments - and what do we permanently give up in each case: shared improvement in the first, or three times the evaluation and governance load in the second? | J7: Three separate deployments sharing the inference platform and the evaluation harness but not the corpus, prompts or guardrail configuration | K7: Solution Architect | L7: CQT0183
A8: D01 | B8: AI SME Chatbot — Learner-Facing | C8: Scope | D8: 1 | E8: Blocker | F8: Before first code | G8: AI | H8: L4 Architect | I8: There are three chatbots on the programme - M15 learner-facing, M23 authoring support and the M27 assessment assistant. Which components do they share as one deployed service and which are duplicated per bot? | J8: share the E04 inference service and one embedding pipeline; keep retrieval, prompts, guardrails and corpora separate per bot | K8: Solution Architect | L8: CQC0010
A9: D01 | B9: AI SME Chatbot — Learner-Facing | C9: Scope | D9: 2 | E9: Blocker | F9: Before sprint 0 | G9: PRODM | H9: L4 Architect | I9: Is practice quiz generation part of the learner chatbot at all, or does every quiz item come from M8 and M27 - because I keep being asked for it in demos? | J9: out of scope for M15; the chatbot may only link to existing M8 items, never generate them | K9: Product Owner | L9: CQC0024
A10: D01 | B10: AI SME Chatbot — Learner-Facing | C10: Scope | D10: 3 | E10: Shaper | F10: Before first release | G10: ID | H10: L1 Junior | I10: Is the learner-facing assistant instructional content subject to the pedagogy gate, or is it a tool that sits outside instructional review entirely? | J10: the assistant is in scope for instructional review of its system prompt, its guidance wording and its refusal messages, but individual generated answers are governed by the AI quality gate instead | K10: Instructional Designer | L10: CQU0127
A11: D01 | B11: AI SME Chatbot — Learner-Facing | C11: Interfaces | D11: 1 | E11: Blocker | F11: Before first code | G11: BE | H11: L1 Junior | I11: Do I call the shared inference service at E04 through the published OpenAI-compatible contract, or does M15 get its own direct model handle on the appliance? | J11: E04 published contract only, with priority class chat on every call and no direct model handle | K11: Solution Architect | L11: CQC0002
A12: D01 | B12: AI SME Chatbot — Learner-Facing | C12: Interfaces | D12: 2 | E12: Blocker | F12: Before first code | G12: BE | H12: L3 Senior | I12: How long do I retain a learner conversation, and is the transcript readable by an instructor, by support, or by nobody? | J12: 90 day retention, learner and support readable with an audit record, instructor access denied by default | K12: Legal & Compliance | L12: CQC0026
A13: D01 | B13: AI SME Chatbot — Learner-Facing | C13: Interfaces | D13: 3 | E13: Shaper | F13: Before first integration | G13: PRODM | H13: L1 Junior | I13: Is the learner-facing chatbot sold as something learners reach directly, or only inside the customer's LMS - because that changes who we are contracting with about learner accounts? | J13: delivered through the customer LMS by default with the customer as controller of learner identity, and a direct-access mode only where a customer has no LMS and accepts the separate terms | K13: Product Owner | L13: CQU0100
A14: D01 | B14: AI SME Chatbot — Learner-Facing | C14: Interfaces | D14: 4 | E14: Shaper | F14: Before first integration | G14: AI | H14: L2 Mid | I14: If E04 activates a new embedding model version, does my index become invalid immediately and who tells me - or do I pin the embedding version per index and refuse mismatched queries? | J14: pin the embedding model version in index metadata and hard-fail any query whose serving version differs, with an operator alert | K14: Another squad | L14: CQC0027
A15: D01 | B15: AI SME Chatbot — Learner-Facing | C15: Data | D15: 1 | E15: Blocker | F15: Before first code | G15: DE | H15: L2 Mid | I15: What are the mandatory fields on every chunk - I have doc ID, revision, effective date and supersedes - and is there anything else retrieval or the UI needs, like page anchor or classification? | J15: doc ID, revision, effective date, supersedes, page anchor, section path, tenant ID and classification marking on every chunk | K15: Data Owner | L15: CQC0015
A16: D01 | B16: AI SME Chatbot — Learner-Facing | C16: Data | D16: 2 | E16: Blocker | F16: Before first code | G16: AI | H16: L2 Mid | I16: When a manual revision is withdrawn, how many minutes or hours may pass before its chunks stop being retrievable - what is the supersession SLA? | J16: HARD BLOCKER - no default possible | K16: NOBODY OWNS THIS | L16: CQC0016
... A2707: XCUT | B2707: Cross-cutting concern / Whole Product | C2707: Handover | D2707: 43 | E2707: Refiner | F2707: Before first release | G2707: SUP | H2707: L4 Architect | I2707: Is there one artefact that documents the whole journey with an owner per hop, and who keeps it current - because I am inheriting support for something described in four separate architecture decks. | J2707: One maintained journey map per major journey listing hops, owning squads, SLOs and runbook links, updated as part of every interface change | K2707: Programme Manager | L2707: CQH0076

Sheet Role Packs
A1: Role Packs
A2: Filter to your role. Work the 'Before sprint 0' block first, then 'Before first code'. Blockers are listed first inside each block.
A4: Role | B4: Role name | C4: Needed by | D4: # | E4: Blocking | F4: Level | G4: ProductID | H4: Stage | I4: Question | J4: Proposed default | K4: Ask | L4: CQID | M4: Answer / decision
A5: FE | B5: Front-End Developer | C5: Before sprint 0 | D5: 1 | E5: Blocker | F5: L1 Junior | G5: E03 | H5: BuildEnv | I5: Do I have a local Moodle with LTI configured that I can develop against, or do I have to book time on a shared instance - because launch work is untestable without one. | J5: A docker-compose Moodle with a pre-registered EdVidura tool and seeded courses, committed to the repository and maintained by the E03 squad. | K5: Another squad | L5: CQA0103
A6: FE | B6: Front-End Developer | C6: Before sprint 0 | D6: 2 | E6: Blocker | F6: L1 Junior | G6: XCUT | H6: Rules | I6: When I am blocked, who do I ask - is there a named technical lead for my squad, or do I post in a channel and wait? | J6: A named squad lead as first point of contact, with a daily standup blocker slot and a visible blocked column on the board | K6: Programme Manager | L6: CQH0241
A7: FE | B7: Front-End Developer | C7: Before sprint 0 | D7: 3 | E7: Blocker | F7: L4 Architect | G7: D24 | H7: Scope | I7: Which platforms does the microlearning app ship on - Android only, Android plus iOS, or a progressive web app - because iOS appears on the platform list for this product but not for the XR store and I need one consistent answer? | J7: One cross-platform client built once and shipped to Android and iOS, with a progressive web fallback explicitly out of scope | K7: Product Owner | L7: CQE0098
A8: FE | B8: Front-End Developer | C8: Before sprint 0 | D8: 4 | E8: Blocker | F8: L4 Architect | G8: E01 | H8: Understand | I8: Which front-end framework are we permanently committing the client's own team to maintain after handover - React, Angular or Vue - and has anyone actually asked what their engineers already know, because this is the single hardest decision to reverse? | J8: React with TypeScript, on the LTS-style release train, because it has the deepest Indian hiring pool - subject to confirmation that the client's team is not an Angular shop | K8: Client SME | L8: CQT0010
A9: FE | B9: Front-End Developer | C9: Before sprint 0 | D9: 5 | E9: Blocker | F9: L4 Architect | G9: E01 | H9: BuildEnv | I9: Do all web surfaces live in one monorepo with a single build and release pipeline, or one repo per product with independent releases - and if separate, do we run micro-frontends behind one shell or entirely separate applications? | J9: One monorepo with independently versioned packages and per-app deploy pipelines; no runtime micro-frontend composition in release one | K9: Solution Architect | L9: CQT0011
A10: FE | B10: Front-End Developer | C10: Before sprint 0 | D10: 6 | E10: Shaper | F10: L1 Junior | G10: XCUT | H10: Understand | I10: What should my first two weeks produce - a running local environment and one merged pull request, or a design document - because I would like to know what good looks like. | J10: Week one: environment running, code checked out, one small merged change. Week two: one real story delivered to the definition of done | K10: Programme Manager | L10: CQH0244
A11: FE | B11: Front-End Developer | C11: Before first code | D11: 1 | E11: Blocker | F11: L1 Junior | G11: D01 | H11: UI/UX | I11: Do I build the chat UI from our own component library or reuse an existing chat component, and where is the design system I am supposed to be using? | J11: build on the EdVidura component library if one exists; otherwise Radix primitives plus our tokens, no third-party chat widget | K11: Product Owner | L11: CQC0029
A12: FE | B12: Front-End Developer | C12: Before first code | D12: 2 | E12: Blocker | F12: L1 Junior | G12: D02 | H12: UI/UX | I12: Where does the grader queue actually live - inside the LMS via an LTI launch, in our own web app, or both - because that changes the whole navigation model? | J12: our own web app with an LTI deep link from the LMS into a specific queue, single sign-on via the platform identity service | K12: Product Owner | L12: CQC0065
A13: FE | B13: Front-End Developer | C13: Before first code | D13: 3 | E13: Blocker | F13: L1 Junior | G13: D11 | H13: Understand | I13: What block types exist in a lesson for slice A - I propose text, image, video, table, procedure step, knowledge check and embedded eBook section - and which of those are actually in scope now? | J13: Those seven block types in slice A, with a registry that allows new types without a schema migration | K13: Instructional Designer | L13: CQD0035
A14: FE | B14: Front-End Developer | C14: Before first code | D14: 4 | E14: Blocker | F14: L1 Junior | G14: D11 | H14: BuildEnv | I14: Which design system and component library do I build the authoring canvas from - is there an EdVidura component library I reuse, or do I build the editor components from scratch? | J14: Reuse the platform component library for chrome and forms, and build only the canvas and block components bespoke on a documented rich-text editor | K14: Solution Architect | L14: CQD0036
A15: FE | B15: Front-End Developer | C15: Before first code | D15: 5 | E15: Blocker | F15: L1 Junior | G15: D12 | H15: BuildEnv | I15: Does the reader ship as a web app, a progressive web app or a native Android and Windows application - because offline reading and encryption at rest push in different directions? | J15: A progressive web app with an installable Android wrapper for offline and encrypted storage | K15: Solution Architect | L15: CQD0089
A16: FE | B16: Front-End Developer | C16: Before first code | D16: 6 | E16: Blocker | F16: L1 Junior | G16: D13 | H16: UI/UX | I16: Does the assistant panel reuse the DCT design system, or does it get its own components - and if the DCT does not have a design system yet, what do I build against? | J16: reuse DCT tokens and primitives; where the DCT has none, define panel-local tokens in a file that can be replaced wholesale later | K16: Product Owner | L16: CQC0100
... A2707: UXD | B2707: UI/UX Designer | C2707: Before first release | D2707: 145 | E2707: Refiner | F2707: L3 Senior | G2707: XCUT | H2707: Handover | I2707: Who owns the design system documentation, and where does a new front-end joiner read how to use it in their first week? | J2707: A published Storybook with usage, do and do not guidance, accessibility notes and token reference, owned by the design system maintainer | K2707: Another squad | L2707: CQH0136

Sheet Decision Agenda
A1: Decision Agenda
A2: One agenda per answerer, ordered by urgency. Run the meeting as a review of the proposed defaults: for each row the answerer says CONFIRM or gives the correction. Rows marked HARD have no default — those must be decided, not defaulted. Rows under 'NOBODY OWNS THIS' are not a meeting; they are an escalation.
A4: Addressed to | B4: # | C4: Needed by | D4: Blocking | E4: Hard? | F4: ProductID | G4: Asked by | H4: Question | I4: Proposed default — confirm or correct | J4: Answer must arrive as | K4: CQID | L4: Decision | M4: Date
A5: Solution Architect | B5: 1 | C5: Before sprint 0 | D5: Blocker | F5: D03 | G5: SEC | H5: Where exactly does the accreditation boundary sit - does it include the cloud build pipeline, the Metabase analytics stack and the local model serving host, or only the enclave runtime - and who draws that line? | I5: Boundary is the enclave runtime plus the media-drop ingest path; the cloud build pipeline is an external connected system documented as an interconnection | J5: decision record | K5: CQF0007
A6: Solution Architect | B6: 2 | C6: Before sprint 0 | D6: Blocker | F6: D06 | G6: DE | H6: Is there one ELRR per enclave that later federates upward, or one central ELRR that enclaves write into - because that choice fixes our network, our identity model and our exit path? | I6: One ELRR per enclave as the authoritative local store, federating summaries upward to an enterprise index | J6: decision record | K6: CQB0025
A7: Solution Architect | B7: 3 | C7: Before sprint 0 | D7: Blocker | F7: D07 | G7: DE | H7: Is the catalogue one enterprise instance or one per organisation with federation between them - and if federated, is a course record copied or referenced across the boundary? | I7: One catalogue per organisation, federating course summaries with a stable global course URI, never copying full records | J7: decision record | K7: CQB0058
A8: Solution Architect | B8: 4 | C8: Before sprint 0 | D8: Blocker | F8: D08 | G8: BE | H8: Is the registry a service other products call at runtime, or a library plus data bundle each product embeds - because the enclave and offline cases push hard toward embedding? | I8: A service with a published embeddable snapshot bundle, so online consumers call it and offline consumers embed it | J8: decision record | K8: CQB0103
A9: Solution Architect | B9: 5 | C9: Before sprint 0 | D9: Blocker | F9: D10 | G9: DEVOPS | H9: Which repository and pipeline do I create the connector in, and which environment names exist for it - I currently have no repo, no pipeline and no environment to deploy to? | I9: New repo edvidura-to-connector in the platform organisation, standard three environments dev, staging, prod, reusing the platform pipeline template | J9: link to existing spec | K9: CQD0016
A10: Solution Architect | B10: 6 | C10: Before sprint 0 | D10: Blocker | F10: D12 | G10: BE | H10: Does D12 own the conversion from source PDF to structured eBook, or does D10 hand me an already-structured document and I only build the reader? | I10: D10 owns acquisition and raw storage; D12 owns OCR, structuring, chunking and the reader | J10: decision record | K10: CQD0070
A11: Solution Architect | B11: 7 | C11: Before sprint 0 | D11: Blocker | F11: D13 | G11: AI | H11: Should the authoring assistant use a different model from the learner chatbot on the same appliance, or must all three assistants share one resident model? | I11: one shared instruction-tuned model for all three assistants until measurement proves a task-specific model is needed | J11: decision record | K11: CQC0079
A12: Solution Architect | B12: 8 | C12: Before sprint 0 | D12: Blocker | F12: D13 | G12: AI | H12: Which parts of M23 are genuinely separate from M15 rather than a different prompt over the same machinery - do I get a shared retrieval library or do I write my own? | I12: M23 reuses the M15 retrieval library as a versioned internal package and owns only its corpus, prompts and guardrails | J12: decision record | K12: CQC0080
A13: Solution Architect | B13: 9 | C13: Before sprint 0 | D13: Blocker | F13: D14 | G13: AI | H13: Is any model inference involved in sequencing at all, or is this purely a rules engine - because that decides whether I am a consumer of the GPU appliance or not? | I13: deterministic rules engine only in v1; no model inference, so no dependency on the shared appliance | J13: decision record | K13: CQC0116
A14: Solution Architect | B14: 10 | C14: Before sprint 0 | D14: Blocker | F14: D15 | G14: DEVOPS | H14: Which repository and which service template do I start D15 in, and does it share a database with the competency registry or have its own? | I14: Own repository, own database, communicating with the registry only over its API | J14: decision record | K14: CQD0129
A15: Solution Architect | B15: 11 | C15: Before sprint 0 | D15: Blocker | F15: D16 | G15: PM | H15: Does profile management own authentication and session, or does Core Platform Identity own that and I only hold the profile record? | I15: Core Platform owns authentication and session; profile management holds the record and its access rules only | J15: decision record | K15: CQB0128
A16: Solution Architect | B16: 12 | C16: Before sprint 0 | D16: Blocker | F16: D16 | G16: BE | H16: Is there one profile store per enclave with an enterprise index above, or one central store all enclaves read - and if central, how does an enclave function when disconnected? | I16: One authoritative profile store per enclave, with an enterprise index holding only pseudonymous keys and coarse summaries | J16: decision record | K16: CQB0130
A17: Solution Architect | B17: 13 | C17: Before sprint 0 | D17: Blocker | E17: HARD | F17: D17 | G17: DE | H17: What unit of data actually crosses the boundary in this pipeline - full xAPI statements, aggregated summaries, or signed assertions - because that single choice determines the schema, the volume, the privacy position and the trust model? | I17: HARD BLOCKER - no default possible | J17: decision record | K17: CQB0143
A18: Solution Architect | B18: 14 | C18: Before sprint 0 | D18: Blocker | F18: D17 | G18: PM | H18: Does this pipeline carry only learning records, or is it the general cross-organisation transport for profiles, catalogue and competency data as well? | I18: One general transport with typed payloads for records, catalogue and competency data; profile data only if the DPDP position permits | J18: decision record | K18: CQB0165
A19: Solution Architect | B19: 15 | C19: Before sprint 0 | D19: Blocker | F19: D17 | G19: BE | H19: Is the pipeline a hub with a central broker, or point-to-point between organisation pairs - because a hub needs an owner nobody has named and point-to-point scales as the square of partners? | I19: Point-to-point for the first three partners with a hub option designed but not built, since a hub requires an owning authority that does not yet exist | J19: decision record | K19: CQB0172
A20: Solution Architect | B20: 16 | C20: Before sprint 0 | D20: Blocker | F20: D18 | G20: BI | H20: We are on Metabase OSS, which has no paid data sandboxing, so per-tenant and per-command isolation has to be enforced in the database rather than in the BI tool - has that been decided, and is anyone still expecting me to buy Metabase Pro instead? | I20: Metabase OSS stays, isolation is enforced by Postgres row-level security on the mart schemas, and Metabase connects as a per-tenant database role rather than one superuser | J20: decision record | K20: CQE0001
A21: Solution Architect | B21: 17 | C21: Before sprint 0 | D21: Blocker | F21: D19 | G21: MXR | H21: Which engine and which version are we building on - Unity or Unreal, and which LTS release - because it is not written anywhere I can find and I cannot set up a build machine without it? | I21: Unity on the current LTS release, pinned in the repo, with the version recorded in the build configuration and upgraded only as a planned activity | J21: decision record | K21: CQT0207
